Workbook
Name SegmentaçãodeDados_CLIENTE: #N/A

Sheet PÁGINA INICIAL
F4: FLUXO DE CAIXA DIÁRIO | H4: =TODAY() -> 46300
A5: EVENTOS EM ANDAMENTO | F5: NOME | G5: PAGAMENTO | H5: ENTRADA | I5: SAÍDA | J5: PAGO
A6: {=_xlfn._xlws.FILTER(EVENTOS[NOME],(EVENTOS[DATA IN]<=TODAY())*(EVENTOS[DATA FN]>=TODAY()),"")} | F6: {=IFERROR(IF(_xlfn._xlws.FILTER(DATABANK[[NOME]:[DESCRIÇÃO]],DATABANK[DATA PGTO]=H4)=0,"",_xlfn._xlws.FILTER(DATABANK[[NOME]:[DESCRIÇÃO]],DATABANK[DATA PGTO]=H4)),"")} | H6: {=IFERROR(IF(_xlfn._xlws.FILTER(DATABANK[[ENTRADA]:[PAGO]],DATABANK[DATA PGTO]=H4)=0,"",_xlfn._xlws.FILTER(DATABANK[[ENTRADA]:[PAGO]],DATABANK[DATA PGTO]=H4)),"")}
A14: EVENTOS PRÓXIMOS | B14: 60
A15: {=IFERROR(_xlfn._xlws.FILTER(EVENTOS[NOME],(EVENTOS[DATA IN]>TODAY())*(EVENTOS[DATA FN]<=(TODAY()+B14)),“”),"")} | B15: =IFERROR(VLOOKUP(A15,EVENTOS[],4,0),"")
B16: =IFERROR(VLOOKUP(A16,EVENTOS[],4,0),"")
B17: =IFERROR(VLOOKUP(A17,EVENTOS[],4,0),"")
B18: =IFERROR(VLOOKUP(A18,EVENTOS[],4,0),"")
B19: =IFERROR(VLOOKUP(A19,EVENTOS[],4,0),"")
B20: =IFERROR(VLOOKUP(A20,EVENTOS[],4,0),"")
B21: =IFERROR(VLOOKUP(A21,EVENTOS[],4,0),"")
B22: =IFERROR(VLOOKUP(A22,EVENTOS[],4,0),"")
B23: =IFERROR(VLOOKUP(A23,EVENTOS[],4,0),"")
B24: =IFERROR(VLOOKUP(A24,EVENTOS[],4,0),"")
B25: =IFERROR(VLOOKUP(A25,EVENTOS[],4,0),"")
B26: =IFERROR(VLOOKUP(A26,EVENTOS[],4,0),"")
B27: =IFERROR(VLOOKUP(A27,EVENTOS[],4,0),"")
... B34: =IFERROR(VLOOKUP(A34,EVENTOS[],4,0),"")

Sheet LANÇAMENTOS
B5: NOME | C5: CLIENTE | D5: LOCAL | E5: DATA IN | F5: DATA FN | G5: ENTRADAS | H5: SAÍDAS | I5: NFE | J5: VALOR TOTAL NFE
G6: {=_xlfn.LET(_xlpm.result,SUM(_xlfn._xlws.FILTER(DATABANK[ENTRADA],DATABANK[NOME]=EVENTOS[[#This Row],[NOME]],"")),IF(_xlpm.result>0,_xlpm.result,"Sem entrada"))} -> Sem entrada | H6: {=_xlfn.LET(_xlpm.result,SUM(_xlfn._xlws.FILTER(DATABANK[SAÍDA],DATABANK[NOME]=EVENTOS[[#This Row],[NOME]],"")),IF(_xlpm.result>0,_xlpm.result,"Sem saída"))} -> Sem saída | I6: {=IF(EVENTOS[[#This Row],[NOME]]="","",_xlfn.TEXTJOIN(", ",1,_xlfn._xlws.FILTER(NFE[NFe],NFE[Evento]=EVENTOS[[#This Row],[NOME]],"Sem NFe")))} | J6: {=IFERROR(SUM(_xlfn._xlws.FILTER(NFE[Valor],NFE[Evento]=EVENTOS[[#This Row],[NOME]])),0)} -> 0
G7: {=_xlfn.LET(_xlpm.result,SUM(_xlfn._xlws.FILTER(DATABANK[ENTRADA],DATABANK[NOME]=EVENTOS[[#This Row],[NOME]],"")),IF(_xlpm.result>0,_xlpm.result,"Sem entrada"))} -> Sem entrada | H7: {=_xlfn.LET(_xlpm.result,SUM(_xlfn._xlws.FILTER(DATABANK[SAÍDA],DATABANK[NOME]=EVENTOS[[#This Row],[NOME]],"")),IF(_xlpm.result>0,_xlpm.result,"Sem saída"))} -> Sem saída | I7: {=IF(EVENTOS[[#This Row],[NOME]]="","",_xlfn.TEXTJOIN(", ",1,_xlfn._xlws.FILTER(NFE[NFe],NFE[Evento]=EVENTOS[[#This Row],[NOME]],"Sem NFe")))} | J7: {=IFERROR(SUM(_xlfn._xlws.FILTER(NFE[Valor],NFE[Evento]=EVENTOS[[#This Row],[NOME]])),0)} -> 0
G8: {=_xlfn.LET(_xlpm.result,SUM(_xlfn._xlws.FILTER(DATABANK[ENTRADA],DATABANK[NOME]=EVENTOS[[#This Row],[NOME]],"")),IF(_xlpm.result>0,_xlpm.result,"Sem entrada"))} -> Sem entrada | H8: {=_xlfn.LET(_xlpm.result,SUM(_xlfn._xlws.FILTER(DATABANK[SAÍDA],DATABANK[NOME]=EVENTOS[[#This Row],[NOME]],"")),IF(_xlpm.result>0,_xlpm.result,"Sem saída"))} -> Sem saída | I8: {=IF(EVENTOS[[#This Row],[NOME]]="","",_xlfn.TEXTJOIN(", ",1,_xlfn._xlws.FILTER(NFE[NFe],NFE[Evento]=EVENTOS[[#This Row],[NOME]],"Sem NFe")))} | J8: {=IFERROR(SUM(_xlfn._xlws.FILTER(NFE[Valor],NFE[Evento]=EVENTOS[[#This Row],[NOME]])),0)} -> 0
G9: {=_xlfn.LET(_xlpm.result,SUM(_xlfn._xlws.FILTER(DATABANK[ENTRADA],DATABANK[NOME]=EVENTOS[[#This Row],[NOME]],"")),IF(_xlpm.result>0,_xlpm.result,"Sem entrada"))} -> Sem entrada | H9: {=_xlfn.LET(_xlpm.result,SUM(_xlfn._xlws.FILTER(DATABANK[SAÍDA],DATABANK[NOME]=EVENTOS[[#This Row],[NOME]],"")),IF(_xlpm.result>0,_xlpm.result,"Sem saída"))} -> Sem saída | I9: {=IF(EVENTOS[[#This Row],[NOME]]="","",_xlfn.TEXTJOIN(", ",1,_xlfn._xlws.FILTER(NFE[NFe],NFE[Evento]=EVENTOS[[#This Row],[NOME]],"Sem NFe")))} | J9: {=IFERROR(SUM(_xlfn._xlws.FILTER(NFE[Valor],NFE[Evento]=EVENTOS[[#This Row],[NOME]])),0)} -> 0
G10: {=_xlfn.LET(_xlpm.result,SUM(_xlfn._xlws.FILTER(DATABANK[ENTRADA],DATABANK[NOME]=EVENTOS[[#This Row],[NOME]],"")),IF(_xlpm.result>0,_xlpm.result,"Sem entrada"))} -> Sem entrada | H10: {=_xlfn.LET(_xlpm.result,SUM(_xlfn._xlws.FILTER(DATABANK[SAÍDA],DATABANK[NOME]=EVENTOS[[#This Row],[NOME]],"")),IF(_xlpm.result>0,_xlpm.result,"Sem saída"))} -> Sem saída | I10: {=IF(EVENTOS[[#This Row],[NOME]]="","",_xlfn.TEXTJOIN(", ",1,_xlfn._xlws.FILTER(NFE[NFe],NFE[Evento]=EVENTOS[[#This Row],[NOME]],"Sem NFe")))} | J10: {=IFERROR(SUM(_xlfn._xlws.FILTER(NFE[Valor],NFE[Evento]=EVENTOS[[#This Row],[NOME]])),0)} -> 0
G11: {=_xlfn.LET(_xlpm.result,SUM(_xlfn._xlws.FILTER(DATABANK[ENTRADA],DATABANK[NOME]=EVENTOS[[#This Row],[NOME]],"")),IF(_xlpm.result>0,_xlpm.result,"Sem entrada"))} -> Sem entrada | H11: {=_xlfn.LET(_xlpm.result,SUM(_xlfn._xlws.FILTER(DATABANK[SAÍDA],DATABANK[NOME]=EVENTOS[[#This Row],[NOME]],"")),IF(_xlpm.result>0,_xlpm.result,"Sem saída"))} -> Sem saída | I11: {=IF(EVENTOS[[#This Row],[NOME]]="","",_xlfn.TEXTJOIN(", ",1,_xlfn._xlws.FILTER(NFE[NFe],NFE[Evento]=EVENTOS[[#This Row],[NOME]],"Sem NFe")))} | J11: {=IFERROR(SUM(_xlfn._xlws.FILTER(NFE[Valor],NFE[Evento]=EVENTOS[[#This Row],[NOME]])),0)} -> 0
G12: {=_xlfn.LET(_xlpm.result,SUM(_xlfn._xlws.FILTER(DATABANK[ENTRADA],DATABANK[NOME]=EVENTOS[[#This Row],[NOME]],"")),IF(_xlpm.result>0,_xlpm.result,"Sem entrada"))} -> Sem entrada | H12: {=_xlfn.LET(_xlpm.result,SUM(_xlfn._xlws.FILTER(DATABANK[SAÍDA],DATABANK[NOME]=EVENTOS[[#This Row],[NOME]],"")),IF(_xlpm.result>0,_xlpm.result,"Sem saída"))} -> Sem saída | J12: {=IFERROR(SUM(_xlfn._xlws.FILTER(NFE[Valor],NFE[Evento]=EVENTOS[[#This Row],[NOME]])),0)} -> 0
G13: {=_xlfn.LET(_xlpm.result,SUM(_xlfn._xlws.FILTER(DATABANK[ENTRADA],DATABANK[NOME]=EVENTOS[[#This Row],[NOME]],"")),IF(_xlpm.result>0,_xlpm.result,"Sem entrada"))} -> Sem entrada | H13: {=_xlfn.LET(_xlpm.result,SUM(_xlfn._xlws.FILTER(DATABANK[SAÍDA],DATABANK[NOME]=EVENTOS[[#This Row],[NOME]],"")),IF(_xlpm.result>0,_xlpm.result,"Sem saída"))} -> Sem saída | J13: {=IFERROR(SUM(_xlfn._xlws.FILTER(NFE[Valor],NFE[Evento]=EVENTOS[[#This Row],[NOME]])),0)} -> 0
G14: {=_xlfn.LET(_xlpm.result,SUM(_xlfn._xlws.FILTER(DATABANK[ENTRADA],DATABANK[NOME]=EVENTOS[[#This Row],[NOME]],"")),IF(_xlpm.result>0,_xlpm.result,"Sem entrada"))} -> Sem entrada | H14: {=_xlfn.LET(_xlpm.result,SUM(_xlfn._xlws.FILTER(DATABANK[SAÍDA],DATABANK[NOME]=EVENTOS[[#This Row],[NOME]],"")),IF(_xlpm.result>0,_xlpm.result,"Sem saída"))} -> Sem saída | J14: {=IFERROR(SUM(_xlfn._xlws.FILTER(NFE[Valor],NFE[Evento]=EVENTOS[[#This Row],[NOME]])),0)} -> 0
G15: {=_xlfn.LET(_xlpm.result,SUM(_xlfn._xlws.FILTER(DATABANK[ENTRADA],DATABANK[NOME]=EVENTOS[[#This Row],[NOME]],"")),IF(_xlpm.result>0,_xlpm.result,"Sem entrada"))} -> Sem entrada | H15: {=_xlfn.LET(_xlpm.result,SUM(_xlfn._xlws.FILTER(DATABANK[SAÍDA],DATABANK[NOME]=EVENTOS[[#This Row],[NOME]],"")),IF(_xlpm.result>0,_xlpm.result,"Sem saída"))} -> Sem saída | J15: {=IFERROR(SUM(_xlfn._xlws.FILTER(NFE[Valor],NFE[Evento]=EVENTOS[[#This Row],[NOME]])),0)} -> 0
G16: {=_xlfn.LET(_xlpm.result,SUM(_xlfn._xlws.FILTER(DATABANK[ENTRADA],DATABANK[NOME]=EVENTOS[[#This Row],[NOME]],"")),IF(_xlpm.result>0,_xlpm.result,"Sem entrada"))} -> Sem entrada | H16: {=_xlfn.LET(_xlpm.result,SUM(_xlfn._xlws.FILTER(DATABANK[SAÍDA],DATABANK[NOME]=EVENTOS[[#This Row],[NOME]],"")),IF(_xlpm.result>0,_xlpm.result,"Sem saída"))} -> Sem saída | J16: {=IFERROR(SUM(_xlfn._xlws.FILTER(NFE[Valor],NFE[Evento]=EVENTOS[[#This Row],[NOME]])),0)} -> 0
G17: {=_xlfn.LET(_xlpm.result,SUM(_xlfn._xlws.FILTER(DATABANK[ENTRADA],DATABANK[NOME]=EVENTOS[[#This Row],[NOME]],"")),IF(_xlpm.result>0,_xlpm.result,"Sem entrada"))} -> Sem entrada | H17: {=_xlfn.LET(_xlpm.result,SUM(_xlfn._xlws.FILTER(DATABANK[SAÍDA],DATABANK[NOME]=EVENTOS[[#This Row],[NOME]],"")),IF(_xlpm.result>0,_xlpm.result,"Sem saída"))} -> Sem saída | J17: {=IFERROR(SUM(_xlfn._xlws.FILTER(NFE[Valor],NFE[Evento]=EVENTOS[[#This Row],[NOME]])),0)} -> 0
G18: {=_xlfn.LET(_xlpm.result,SUM(_xlfn._xlws.FILTER(DATABANK[ENTRADA],DATABANK[NOME]=EVENTOS[[#This Row],[NOME]],"")),IF(_xlpm.result>0,_xlpm.result,"Sem entrada"))} -> Sem entrada | H18: {=_xlfn.LET(_xlpm.result,SUM(_xlfn._xlws.FILTER(DATABANK[SAÍDA],DATABANK[NOME]=EVENTOS[[#This Row],[NOME]],"")),IF(_xlpm.result>0,_xlpm.result,"Sem saída"))} -> Sem saída | J18: {=IFERROR(SUM(_xlfn._xlws.FILTER(NFE[Valor],NFE[Evento]=EVENTOS[[#This Row],[NOME]])),0)} -> 0
G19: {=_xlfn.LET(_xlpm.result,SUM(_xlfn._xlws.FILTER(DATABANK[ENTRADA],DATABANK[NOME]=EVENTOS[[#This Row],[NOME]],"")),IF(_xlpm.result>0,_xlpm.result,"Sem entrada"))} -> Sem entrada | H19: {=_xlfn.LET(_xlpm.result,SUM(_xlfn._xlws.FILTER(DATABANK[SAÍDA],DATABANK[NOME]=EVENTOS[[#This Row],[NOME]],"")),IF(_xlpm.result>0,_xlpm.result,"Sem saída"))} -> Sem saída | J19: {=IFERROR(SUM(_xlfn._xlws.FILTER(NFE[Valor],NFE[Evento]=EVENTOS[[#This Row],[NOME]])),0)} -> 0
G20: {=_xlfn.LET(_xlpm.result,SUM(_xlfn._xlws.FILTER(DATABANK[ENTRADA],DATABANK[NOME]=EVENTOS[[#This Row],[NOME]],"")),IF(_xlpm.result>0,_xlpm.result,"Sem entrada"))} -> Sem entrada | H20: {=_xlfn.LET(_xlpm.result,SUM(_xlfn._xlws.FILTER(DATABANK[SAÍDA],DATABANK[NOME]=EVENTOS[[#This Row],[NOME]],"")),IF(_xlpm.result>0,_xlpm.result,"Sem saída"))} -> Sem saída | J20: {=IFERROR(SUM(_xlfn._xlws.FILTER(NFE[Valor],NFE[Evento]=EVENTOS[[#This Row],[NOME]])),0)} -> 0
G21: {=_xlfn.LET(_xlpm.result,SUM(_xlfn._xlws.FILTER(DATABANK[ENTRADA],DATABANK[NOME]=EVENTOS[[#This Row],[NOME]],"")),IF(_xlpm.result>0,_xlpm.result,"Sem entrada"))} -> Sem entrada | H21: {=_xlfn.LET(_xlpm.result,SUM(_xlfn._xlws.FILTER(DATABANK[SAÍDA],DATABANK[NOME]=EVENTOS[[#This Row],[NOME]],"")),IF(_xlpm.result>0,_xlpm.result,"Sem saída"))} -> Sem saída | J21: {=IFERROR(SUM(_xlfn._xlws.FILTER(NFE[Valor],NFE[Evento]=EVENTOS[[#This Row],[NOME]])),0)} -> 0
G22: {=_xlfn.LET(_xlpm.result,SUM(_xlfn._xlws.FILTER(DATABANK[ENTRADA],DATABANK[NOME]=EVENTOS[[#This Row],[NOME]],"")),IF(_xlpm.result>0,_xlpm.result,"Sem entrada"))} -> Sem entrada | H22: {=_xlfn.LET(_xlpm.result,SUM(_xlfn._xlws.FILTER(DATABANK[SAÍDA],DATABANK[NOME]=EVENTOS[[#This Row],[NOME]],"")),IF(_xlpm.result>0,_xlpm.result,"Sem saída"))} -> Sem saída | J22: {=IFERROR(SUM(_xlfn._xlws.FILTER(NFE[Valor],NFE[Evento]=EVENTOS[[#This Row],[NOME]])),0)} -> 0
G23: {=_xlfn.LET(_xlpm.result,SUM(_xlfn._xlws.FILTER(DATABANK[ENTRADA],DATABANK[NOME]=EVENTOS[[#This Row],[NOME]],"")),IF(_xlpm.result>0,_xlpm.result,"Sem entrada"))} -> Sem entrada | H23: {=_xlfn.LET(_xlpm.result,SUM(_xlfn._xlws.FILTER(DATABANK[SAÍDA],DATABANK[NOME]=EVENTOS[[#This Row],[NOME]],"")),IF(_xlpm.result>0,_xlpm.result,"Sem saída"))} -> Sem saída | J23: {=IFERROR(SUM(_xlfn._xlws.FILTER(NFE[Valor],NFE[Evento]=EVENTOS[[#This Row],[NOME]])),0)} -> 0
... G70: {=_xlfn.LET(_xlpm.result,SUM(_xlfn._xlws.FILTER(DATABANK[ENTRADA],DATABANK[NOME]=EVENTOS[[#This Row],[NOME]],"")),IF(_xlpm.result>0,_xlpm.result,"Sem entrada"))} -> Sem entrada | H70: {=_xlfn.LET(_xlpm.result,SUM(_xlfn._xlws.FILTER(DATABANK[SAÍDA],DATABANK[NOME]=EVENTOS[[#This Row],[NOME]],"")),IF(_xlpm.result>0,_xlpm.result,"Sem saída"))} -> Sem saída | J70: {=IFERROR(SUM(_xlfn._xlws.FILTER(NFE[Valor],NFE[Evento]=EVENTOS[[#This Row],[NOME]])),0)} -> 0
G71: {=_xlfn.LET(_xlpm.result,SUM(_xlfn._xlws.FILTER(DATABANK[ENTRADA],DATABANK[NOME]=EVENTOS[[#This Row],[NOME]],"")),IF(_xlpm.result>0,_xlpm.result,"Sem entrada"))} -> Sem entrada | H71: {=_xlfn.LET(_xlpm.result,SUM(_xlfn._xlws.FILTER(DATABANK[SAÍDA],DATABANK[NOME]=EVENTOS[[#This Row],[NOME]],"")),IF(_xlpm.result>0,_xlpm.result,"Sem saída"))} -> Sem saída | I71: {=IF(EVENTOS[[#This Row],[NOME]]="","",_xlfn.TEXTJOIN(", ",1,_xlfn._xlws.FILTER(NFE[NFe],NFE[Evento]=EVENTOS[[#This Row],[NOME]],"Sem NFe")))} | J71: {=IFERROR(SUM(_xlfn._xlws.FILTER(NFE[Valor],NFE[Evento]=EVENTOS[[#This Row],[NOME]])),0)} -> 0
G72: {=_xlfn.LET(_xlpm.result,SUM(_xlfn._xlws.FILTER(DATABANK[ENTRADA],DATABANK[NOME]=EVENTOS[[#This Row],[NOME]],"")),IF(_xlpm.result>0,_xlpm.result,"Sem entrada"))} -> Sem entrada | H72: {=_xlfn.LET(_xlpm.result,SUM(_xlfn._xlws.FILTER(DATABANK[SAÍDA],DATABANK[NOME]=EVENTOS[[#This Row],[NOME]],"")),IF(_xlpm.result>0,_xlpm.result,"Sem saída"))} -> Sem saída | I72: {=IF(EVENTOS[[#This Row],[NOME]]="","",_xlfn.TEXTJOIN(", ",1,_xlfn._xlws.FILTER(NFE[NFe],NFE[Evento]=EVENTOS[[#This Row],[NOME]],"Sem NFe")))} | J72: {=IFERROR(SUM(_xlfn._xlws.FILTER(NFE[Valor],NFE[Evento]=EVENTOS[[#This Row],[NOME]])),0)} -> 0
G73: {=_xlfn.LET(_xlpm.result,SUM(_xlfn._xlws.FILTER(DATABANK[ENTRADA],DATABANK[NOME]=EVENTOS[[#This Row],[NOME]],"")),IF(_xlpm.result>0,_xlpm.result,"Sem entrada"))} -> Sem entrada | H73: {=_xlfn.LET(_xlpm.result,SUM(_xlfn._xlws.FILTER(DATABANK[SAÍDA],DATABANK[NOME]=EVENTOS[[#This Row],[NOME]],"")),IF(_xlpm.result>0,_xlpm.result,"Sem saída"))} -> Sem saída | I73: {=IF(EVENTOS[[#This Row],[NOME]]="","",_xlfn.TEXTJOIN(", ",1,_xlfn._xlws.FILTER(NFE[NFe],NFE[Evento]=EVENTOS[[#This Row],[NOME]],"Sem NFe")))} | J73: {=IFERROR(SUM(_xlfn._xlws.FILTER(NFE[Valor],NFE[Evento]=EVENTOS[[#This Row],[NOME]])),0)} -> 0
G74: {=_xlfn.LET(_xlpm.result,SUM(_xlfn._xlws.FILTER(DATABANK[ENTRADA],DATABANK[NOME]=EVENTOS[[#This Row],[NOME]],"")),IF(_xlpm.result>0,_xlpm.result,"Sem entrada"))} -> Sem entrada | H74: {=_xlfn.LET(_xlpm.result,SUM(_xlfn._xlws.FILTER(DATABANK[SAÍDA],DATABANK[NOME]=EVENTOS[[#This Row],[NOME]],"")),IF(_xlpm.result>0,_xlpm.result,"Sem saída"))} -> Sem saída | I74: {=IF(EVENTOS[[#This Row],[NOME]]="","",_xlfn.TEXTJOIN(", ",1,_xlfn._xlws.FILTER(NFE[NFe],NFE[Evento]=EVENTOS[[#This Row],[NOME]],"Sem NFe")))} | J74: {=IFERROR(SUM(_xlfn._xlws.FILTER(NFE[Valor],NFE[Evento]=EVENTOS[[#This Row],[NOME]])),0)} -> 0
G75: {=_xlfn.LET(_xlpm.result,SUM(_xlfn._xlws.FILTER(DATABANK[ENTRADA],DATABANK[NOME]=EVENTOS[[#This Row],[NOME]],"")),IF(_xlpm.result>0,_xlpm.result,"Sem entrada"))} -> Sem entrada | H75: {=_xlfn.LET(_xlpm.result,SUM(_xlfn._xlws.FILTER(DATABANK[SAÍDA],DATABANK[NOME]=EVENTOS[[#This Row],[NOME]],"")),IF(_xlpm.result>0,_xlpm.result,"Sem saída"))} -> Sem saída | I75: {=IF(EVENTOS[[#This Row],[NOME]]="","",_xlfn.TEXTJOIN(", ",1,_xlfn._xlws.FILTER(NFE[NFe],NFE[Evento]=EVENTOS[[#This Row],[NOME]],"Sem NFe")))} | J75: {=IFERROR(SUM(_xlfn._xlws.FILTER(NFE[Valor],NFE[Evento]=EVENTOS[[#This Row],[NOME]])),0)} -> 0
G76: {=_xlfn.LET(_xlpm.result,SUM(_xlfn._xlws.FILTER(DATABANK[ENTRADA],DATABANK[NOME]=EVENTOS[[#This Row],[NOME]],"")),IF(_xlpm.result>0,_xlpm.result,"Sem entrada"))} -> Sem entrada | H76: {=_xlfn.LET(_xlpm.result,SUM(_xlfn._xlws.FILTER(DATABANK[SAÍDA],DATABANK[NOME]=EVENTOS[[#This Row],[NOME]],"")),IF(_xlpm.result>0,_xlpm.result,"Sem saída"))} -> Sem saída | I76: {=IF(EVENTOS[[#This Row],[NOME]]="","",_xlfn.TEXTJOIN(", ",1,_xlfn._xlws.FILTER(NFE[NFe],NFE[Evento]=EVENTOS[[#This Row],[NOME]],"Sem NFe")))} | J76: {=IFERROR(SUM(_xlfn._xlws.FILTER(NFE[Valor],NFE[Evento]=EVENTOS[[#This Row],[NOME]])),0)} -> 0
G77: {=_xlfn.LET(_xlpm.result,SUM(_xlfn._xlws.FILTER(DATABANK[ENTRADA],DATABANK[NOME]=EVENTOS[[#This Row],[NOME]],"")),IF(_xlpm.result>0,_xlpm.result,"Sem entrada"))} -> Sem entrada | H77: {=_xlfn.LET(_xlpm.result,SUM(_xlfn._xlws.FILTER(DATABANK[SAÍDA],DATABANK[NOME]=EVENTOS[[#This Row],[NOME]],"")),IF(_xlpm.result>0,_xlpm.result,"Sem saída"))} -> Sem saída | I77: {=IF(EVENTOS[[#This Row],[NOME]]="","",_xlfn.TEXTJOIN(", ",1,_xlfn._xlws.FILTER(NFE[NFe],NFE[Evento]=EVENTOS[[#This Row],[NOME]],"Sem NFe")))} | J77: {=IFERROR(SUM(_xlfn._xlws.FILTER(NFE[Valor],NFE[Evento]=EVENTOS[[#This Row],[NOME]])),0)} -> 0
G78: {=_xlfn.LET(_xlpm.result,SUM(_xlfn._xlws.FILTER(DATABANK[ENTRADA],DATABANK[NOME]=EVENTOS[[#This Row],[NOME]],"")),IF(_xlpm.result>0,_xlpm.result,"Sem entrada"))} -> Sem entrada | H78: {=_xlfn.LET(_xlpm.result,SUM(_xlfn._xlws.FILTER(DATABANK[SAÍDA],DATABANK[NOME]=EVENTOS[[#This Row],[NOME]],"")),IF(_xlpm.result>0,_xlpm.result,"Sem saída"))} -> Sem saída | I78: {=IF(EVENTOS[[#This Row],[NOME]]="","",_xlfn.TEXTJOIN(", ",1,_xlfn._xlws.FILTER(NFE[NFe],NFE[Evento]=EVENTOS[[#This Row],[NOME]],"Sem NFe")))} | J78: {=IFERROR(SUM(_xlfn._xlws.FILTER(NFE[Valor],NFE[Evento]=EVENTOS[[#This Row],[NOME]])),0)} -> 0
G79: {=_xlfn.LET(_xlpm.result,SUM(_xlfn._xlws.FILTER(DATABANK[ENTRADA],DATABANK[NOME]=EVENTOS[[#This Row],[NOME]],"")),IF(_xlpm.result>0,_xlpm.result,"Sem entrada"))} -> Sem entrada | H79: {=_xlfn.LET(_xlpm.result,SUM(_xlfn._xlws.FILTER(DATABANK[SAÍDA],DATABANK[NOME]=EVENTOS[[#This Row],[NOME]],"")),IF(_xlpm.result>0,_xlpm.result,"Sem saída"))} -> Sem saída | I79: {=IF(EVENTOS[[#This Row],[NOME]]="","",_xlfn.TEXTJOIN(", ",1,_xlfn._xlws.FILTER(NFE[NFe],NFE[Evento]=EVENTOS[[#This Row],[NOME]],"Sem NFe")))} | J79: {=IFERROR(SUM(_xlfn._xlws.FILTER(NFE[Valor],NFE[Evento]=EVENTOS[[#This Row],[NOME]])),0)} -> 0
G80: {=_xlfn.LET(_xlpm.result,SUM(_xlfn._xlws.FILTER(DATABANK[ENTRADA],DATABANK[NOME]=EVENTOS[[#This Row],[NOME]],"")),IF(_xlpm.result>0,_xlpm.result,"Sem entrada"))} -> Sem entrada | H80: {=_xlfn.LET(_xlpm.result,SUM(_xlfn._xlws.FILTER(DATABANK[SAÍDA],DATABANK[NOME]=EVENTOS[[#This Row],[NOME]],"")),IF(_xlpm.result>0,_xlpm.result,"Sem saída"))} -> Sem saída | I80: {=IF(EVENTOS[[#This Row],[NOME]]="","",_xlfn.TEXTJOIN(", ",1,_xlfn._xlws.FILTER(NFE[NFe],NFE[Evento]=EVENTOS[[#This Row],[NOME]],"Sem NFe")))} | J80: {=IFERROR(SUM(_xlfn._xlws.FILTER(NFE[Valor],NFE[Evento]=EVENTOS[[#This Row],[NOME]])),0)} -> 0
G81: {=_xlfn.LET(_xlpm.result,SUM(_xlfn._xlws.FILTER(DATABANK[ENTRADA],DATABANK[NOME]=EVENTOS[[#This Row],[NOME]],"")),IF(_xlpm.result>0,_xlpm.result,"Sem entrada"))} -> Sem entrada | H81: {=_xlfn.LET(_xlpm.result,SUM(_xlfn._xlws.FILTER(DATABANK[SAÍDA],DATABANK[NOME]=EVENTOS[[#This Row],[NOME]],"")),IF(_xlpm.result>0,_xlpm.result,"Sem saída"))} -> Sem saída | I81: {=IF(EVENTOS[[#This Row],[NOME]]="","",_xlfn.TEXTJOIN(", ",1,_xlfn._xlws.FILTER(NFE[NFe],NFE[Evento]=EVENTOS[[#This Row],[NOME]],"Sem NFe")))} | J81: {=IFERROR(SUM(_xlfn._xlws.FILTER(NFE[Valor],NFE[Evento]=EVENTOS[[#This Row],[NOME]])),0)} -> 0
G82: {=_xlfn.LET(_xlpm.result,SUM(_xlfn._xlws.FILTER(DATABANK[ENTRADA],DATABANK[NOME]=EVENTOS[[#This Row],[NOME]],"")),IF(_xlpm.result>0,_xlpm.result,"Sem entrada"))} -> Sem entrada | H82: {=_xlfn.LET(_xlpm.result,SUM(_xlfn._xlws.FILTER(DATABANK[SAÍDA],DATABANK[NOME]=EVENTOS[[#This Row],[NOME]],"")),IF(_xlpm.result>0,_xlpm.result,"Sem saída"))} -> Sem saída | I82: {=IF(EVENTOS[[#This Row],[NOME]]="","",_xlfn.TEXTJOIN(", ",1,_xlfn._xlws.FILTER(NFE[NFe],NFE[Evento]=EVENTOS[[#This Row],[NOME]],"Sem NFe")))} | J82: {=IFERROR(SUM(_xlfn._xlws.FILTER(NFE[Valor],NFE[Evento]=EVENTOS[[#This Row],[NOME]])),0)} -> 0
... G137: {=_xlfn.LET(_xlpm.result,SUM(_xlfn._xlws.FILTER(DATABANK[ENTRADA],DATABANK[NOME]=EVENTOS[[#This Row],[NOME]],"")),IF(_xlpm.result>0,_xlpm.result,"Sem entrada"))} -> Sem entrada | H137: {=_xlfn.LET(_xlpm.result,SUM(_xlfn._xlws.FILTER(DATABANK[SAÍDA],DATABANK[NOME]=EVENTOS[[#This Row],[NOME]],"")),IF(_xlpm.result>0,_xlpm.result,"Sem saída"))} -> Sem saída | I137: {=IF(EVENTOS[[#This Row],[NOME]]="","",_xlfn.TEXTJOIN(", ",1,_xlfn._xlws.FILTER(NFE[NFe],NFE[Evento]=EVENTOS[[#This Row],[NOME]],"Sem NFe")))} | J137: {=IFERROR(SUM(_xlfn._xlws.FILTER(NFE[Valor],NFE[Evento]=EVENTOS[[#This Row],[NOME]])),0)} -> 0

Sheet DADOS
A4: CATEGORIA | B4: NOME | C4: DESCRIÇÃO | D4: DATA PGTO | E4: ENTRADA | F4: SAÍDA | G4: PAGO | H4: CLIENTE | I4: OBS
H5: =IFERROR(INDEX(EVENTOS[[NOME]:[CLIENTE]],MATCH(DATABANK[[#This Row],[NOME]],EVENTOS[NOME],0),2),"")
H6: =IFERROR(INDEX(EVENTOS[[NOME]:[CLIENTE]],MATCH(DATABANK[[#This Row],[NOME]],EVENTOS[NOME],0),2),"")
H7: =IFERROR(INDEX(EVENTOS[[NOME]:[CLIENTE]],MATCH(DATABANK[[#This Row],[NOME]],EVENTOS[NOME],0),2),"")
H8: =IFERROR(INDEX(EVENTOS[[NOME]:[CLIENTE]],MATCH(DATABANK[[#This Row],[NOME]],EVENTOS[NOME],0),2),"")
H9: =IFERROR(INDEX(EVENTOS[[NOME]:[CLIENTE]],MATCH(DATABANK[[#This Row],[NOME]],EVENTOS[NOME],0),2),"")
H10: =IFERROR(INDEX(EVENTOS[[NOME]:[CLIENTE]],MATCH(DATABANK[[#This Row],[NOME]],EVENTOS[NOME],0),2),"")
H11: =IFERROR(INDEX(EVENTOS[[NOME]:[CLIENTE]],MATCH(DATABANK[[#This Row],[NOME]],EVENTOS[NOME],0),2),"")
H12: =IFERROR(INDEX(EVENTOS[[NOME]:[CLIENTE]],MATCH(DATABANK[[#This Row],[NOME]],EVENTOS[NOME],0),2),"")
H13: =IFERROR(INDEX(EVENTOS[[NOME]:[CLIENTE]],MATCH(DATABANK[[#This Row],[NOME]],EVENTOS[NOME],0),2),"")
H14: =IFERROR(INDEX(EVENTOS[[NOME]:[CLIENTE]],MATCH(DATABANK[[#This Row],[NOME]],EVENTOS[NOME],0),2),"")
H15: =IFERROR(INDEX(EVENTOS[[NOME]:[CLIENTE]],MATCH(DATABANK[[#This Row],[NOME]],EVENTOS[NOME],0),2),"")
H16: =IFERROR(INDEX(EVENTOS[[NOME]:[CLIENTE]],MATCH(DATABANK[[#This Row],[NOME]],EVENTOS[NOME],0),2),"")
... H3143: =IFERROR(INDEX(EVENTOS[[NOME]:[CLIENTE]],MATCH(DATABANK[[#This Row],[NOME]],EVENTOS[NOME],0),2),"")

Sheet ANOTAÇÕES
A2: Coluna1 | B2: Coluna2 | C2: Coluna3 | D2: Coluna4 | E2: Coluna5 | F2: Coluna6 | G2: Coluna7

Sheet GANTT
B1: JANEIRO | AG1: FEVEREIRO | BI1: MARÇO | CN1: ABRIL | DR1: MAIO | EW1: JUNHO | GA1: JULHO | HF1: AGOSTO | IK1: SETEMBRO | JO1: OUTUBRO | KT1: NOVEMBRO | LX1: DEZEMBRO
B2: 45658 | C2: 45659 | D2: 45660 | E2: 45661 | F2: 45662 | G2: 45663 | H2: 45664 | I2: 45665 | J2: 45666 | K2: 45667 | L2: 45668 | M2: 45669 | N2: 45670 | O2: 45671 | P2: 45672 | Q2: 45673 | R2: 45674 | S2: 45675 | T2: 45676 | U2: 45677 | V2: 45678 | W2: 45679 | X2: 45680 | Y2: 45681 | Z2: 45682 | AA2: 45683 | AB2: 45684 | AC2: 45685 | AD2: 45686 | AE2: 45687 | AF2: 45688 | AG2: 45689 | AH2: 45690 | AI2: 45691 | AJ2: 45692 | AK2: 45693 | AL2: 45694 | AM2: 45695 | AN2: 45696 | AO2: 45697 | AP2: 45698 | AQ2: 45699 | AR2: 45700 | AS2: 45701 | AT2: 45702 | AU2: 45703 | AV2: 45704 | AW2: 45705 | AX2: 45706 | AY2: 45707 | AZ2: 45708 | BA2: 45709 | BB2: 45710 | BC2: 45711 | BD2: 45712 | BE2: 45713 | BF2: 45714 | BG2: 45715 | BH2: 45716 | BI2: 45717 | BJ2: 45718 | BK2: 45719 | BL2: 45720 | BM2: 45721 | BN2: 45722 | BO2: 45723 | BP2: 45724 | BQ2: 45725 | BR2: 45726 | BS2: 45727 | BT2: 45728 | BU2: 45729 | BV2: 45730 | BW2: 45731 | BX2: 45732 | BY2: 45733 | BZ2: 45734 | CA2: 45735 | CB2: 45736 | CC2: 45737 | CD2: 45738 | CE2: 45739 | CF2: 45740 | CG2: 45741 | CH2: 45742 | CI2: 45743 | CJ2: 45744 | CK2: 45745 | CL2: 45746 | CM2: 45747 | CN2: 45748 | CO2: 45749 | CP2: 45750 | CQ2: 45751 | CR2: 45752 | CS2: 45753 | CT2: 45754 | CU2: 45755 | CV2: 45756 | CW2: 45757 | CX2: 45758 | CY2: 45759 | CZ2: 45760 | DA2: 45761 | DB2: 45762 | DC2: 45763 | DD2: 45764 | DE2: 45765 | DF2: 45766 | DG2: 45767 | DH2: 45768 | DI2: 45769 | DJ2: 45770 | DK2: 45771 | DL2: 45772 | DM2: 45773 | DN2: 45774 | DO2: 45775 | DP2: 45776 | DQ2: 45777 | DR2: 45778 | DS2: 45779 | DT2: 45780 | DU2: 45781 | DV2: 45782 | DW2: 45783 | DX2: 45784 | DY2: 45785 | DZ2: 45786 | EA2: 45787 | EB2: 45788 | EC2: 45789 | ED2: 45790 | EE2: 45791 | EF2: 45792 | EG2: 45793 | EH2: 45794 | EI2: 45795 | EJ2: 45796 | EK2: 45797 | EL2: 45798 | EM2: 45799 | EN2: 45800 | EO2: 45801 | EP2: 45802 | EQ2: 45803 | ER2: 45804 | ES2: 45805 | ET2: 45806 | EU2: 45807 | EV2: 45808 | EW2: 45809 | EX2: 45810 | EY2: 45811 | EZ2: 45812 | FA2: 45813 | FB2: 45814 | FC2: 45815 | FD2: 45816 | FE2: 45817 | FF2: 45818 | FG2: 45819 | FH2: 45820 | FI2: 45821 | FJ2: 45822 | FK2: 45823 | FL2: 45824 | FM2: 45825 | FN2: 45826 | FO2: 45827 | FP2: 45828 | FQ2: 45829 | FR2: 45830 | FS2: 45831 | FT2: 45832 | FU2: 45833 | FV2: 45834 | FW2: 45835 | FX2: 45836 | FY2: 45837 | FZ2: 45838 | GA2: 45839 | GB2: 45840 | GC2: 45841 | GD2: 45842 | GE2: 45843 | GF2: 45844 | GG2: 45845 | GH2: 45846 | GI2: 45847 | GJ2: 45848 | GK2: 45849 | GL2: 45850 | GM2: 45851 | GN2: 45852 | GO2: 45853 | GP2: 45854 | GQ2: 45855 | GR2: 45856 | GS2: 45857 | GT2: 45858 | GU2: 45859 | GV2: 45860 | GW2: 45861 | GX2: 45862 | GY2: 45863 | GZ2: 45864 | HA2: 45865 | HB2: 45866 | HC2: 45867 | HD2: 45868 | HE2: 45869 | HF2: 45870 | HG2: 45871 | HH2: 45872 | HI2: 45873 | HJ2: 45874 | HK2: 45875 | HL2: 45876 | HM2: 45877 | HN2: 45878 | HO2: 45879 | HP2: 45880 | HQ2: 45881 | HR2: 45882 | HS2: 45883 | HT2: 45884 | HU2: 45885 | HV2: 45886 | HW2: 45887 | HX2: 45888 | HY2: 45889 | HZ2: 45890 | IA2: 45891 | IB2: 45892 | IC2: 45893 | ID2: 45894 | IE2: 45895 | IF2: 45896 | IG2: 45897 | IH2: 45898 | II2: 45899 | IJ2: 45900 | IK2: 45901 | IL2: 45902 | IM2: 45903 | IN2: 45904 | IO2: 45905 | IP2: 45906 | IQ2: 45907 | IR2: 45908 | IS2: 45909 | IT2: 45910 | IU2: 45911 | IV2: 45912 | IW2: 45913 | IX2: 45914 | IY2: 45915 | IZ2: 45916 | JA2: 45917 | JB2: 45918 | JC2: 45919 | JD2: 45920 | JE2: 45921 | JF2: 45922 | JG2: 45923 | JH2: 45924 | JI2: 45925 | JJ2: 45926 | JK2: 45927 | JL2: 45928 | JM2: 45929 | JN2: 45930 | JO2: 45931 | JP2: 45932 | JQ2: 45933 | JR2: 45934 | JS2: 45935 | JT2: 45936 | JU2: 45937 | JV2: 45938 | JW2: 45939 | JX2: 45940 | JY2: 45941 | JZ2: 45942 | KA2: 45943 | KB2: 45944 | KC2: 45945 | KD2: 45946 | KE2: 45947 | KF2: 45948 | KG2: 45949 | KH2: 45950 | KI2: 45951 | KJ2: 45952 | KK2: 45953 | KL2: 45954 | KM2: 45955 | KN2: 45956 | KO2: 45957 | KP2: 45958 | KQ2: 45959 | KR2: 45960 | KS2: 45961 | KT2: 45962 | KU2: 45963 | KV2: 45964 | KW2: 45965 | KX2: 45966 | KY2: 45967 | KZ2: 45968 | LA2: 45969 | LB2: 45970 | LC2: 45971 | LD2: 45972 | LE2: 45973 | LF2: 45974 | LG2: 45975 | LH2: 45976 | LI2: 45977 | LJ2: 45978 | LK2: 45979 | LL2: 45980 | LM2: 45981 | LN2: 45982 | LO2: 45983 | LP2: 45984 | LQ2: 45985 | LR2: 45986 | LS2: 45987 | LT2: 45988 | LU2: 45989 | LV2: 45990 | LW2: 45991 | LX2: 45992 | LY2: 45993 | LZ2: 45994 | MA2: 45995 | MB2: 45996 | MC2: 45997 | MD2: 45998 | ME2: 45999 | MF2: 46000 | MG2: 46001 | MH2: 46002 | MI2: 46003 | MJ2: 46004 | MK2: 46005 | ML2: 46006 | MM2: 46007 | MN2: 46008 | MO2: 46009 | MP2: 46010 | MQ2: 46011 | MR2: 46012 | MS2: 46013 | MT2: 46014 | MU2: 46015 | MV2: 46016 | MW2: 46017 | MX2: 46018 | MY2: 46019 | MZ2: 46020 | NA2: 46021 | NB2: 46022
A3: {=_xlfn.UNIQUE(IF(EVENTOS[NOME]=0,"",EVENTOS[NOME]))}

Sheet FORNECEDORES
A2: Nome | B2: CPF | C2: RG | D2: PIX | E2: Tipo | F2: Função | G2: Contato | H2: Cidade | I2: UF | J2: Observações

Sheet NFE
A2: Evento | B2: NFe | C2: Valor | D2: Imposto M | E2: Imposto T | F2: Entrada | G2: Valor Real | H2: Diferença -Taxa | I2: Data Emissão
D3: =NFE[[#This Row],[Valor]]*0.0615 -> 0 | E3: =NFE[[#This Row],[Valor]]*0.0768 -> 0 | F3: =NFE[[#This Row],[Valor]]-(NFE[[#This Row],[Valor]]*0.0615) -> 0 | H3: =(((NFE[[#This Row],[Valor]]-NFE[[#This Row],[Valor Real]])*0.1383)-(NFE[[#This Row],[Valor]]-NFE[[#This Row],[Valor Real]]))*-1 -> 0
D4: =NFE[[#This Row],[Valor]]*0.0615 -> 0 | E4: =NFE[[#This Row],[Valor]]*0.0768 -> 0 | F4: =NFE[[#This Row],[Valor]]-(NFE[[#This Row],[Valor]]*0.0615) -> 0 | H4: =(((NFE[[#This Row],[Valor]]-NFE[[#This Row],[Valor Real]])*0.1383)-(NFE[[#This Row],[Valor]]-NFE[[#This Row],[Valor Real]]))*-1 -> 0
D5: =NFE[[#This Row],[Valor]]*0.0615 -> 0 | E5: =NFE[[#This Row],[Valor]]*0.0768 -> 0 | F5: =NFE[[#This Row],[Valor]]-(NFE[[#This Row],[Valor]]*0.0615) -> 0 | H5: =(((NFE[[#This Row],[Valor]]-NFE[[#This Row],[Valor Real]])*0.1383)-(NFE[[#This Row],[Valor]]-NFE[[#This Row],[Valor Real]]))*-1 -> 0
D6: =NFE[[#This Row],[Valor]]*0.0615 -> 0 | E6: =NFE[[#This Row],[Valor]]*0.0768 -> 0 | F6: =NFE[[#This Row],[Valor]]-(NFE[[#This Row],[Valor]]*0.0615) -> 0 | H6: =(((NFE[[#This Row],[Valor]]-NFE[[#This Row],[Valor Real]])*0.1383)-(NFE[[#This Row],[Valor]]-NFE[[#This Row],[Valor Real]]))*-1 -> 0
D7: =NFE[[#This Row],[Valor]]*0.0615 -> 0 | E7: =NFE[[#This Row],[Valor]]*0.0768 -> 0 | F7: =NFE[[#This Row],[Valor]]-(NFE[[#This Row],[Valor]]*0.0615) -> 0 | H7: =(((NFE[[#This Row],[Valor]]-NFE[[#This Row],[Valor Real]])*0.1383)-(NFE[[#This Row],[Valor]]-NFE[[#This Row],[Valor Real]]))*-1 -> 0
D8: =NFE[[#This Row],[Valor]]*0.0615 -> 0 | E8: =NFE[[#This Row],[Valor]]*0.0768 -> 0 | F8: =NFE[[#This Row],[Valor]]-(NFE[[#This Row],[Valor]]*0.0615) -> 0 | H8: =(((NFE[[#This Row],[Valor]]-NFE[[#This Row],[Valor Real]])*0.1383)-(NFE[[#This Row],[Valor]]-NFE[[#This Row],[Valor Real]]))*-1 -> 0
D9: =NFE[[#This Row],[Valor]]*0.0615 -> 0 | E9: =NFE[[#This Row],[Valor]]*0.0768 -> 0 | F9: =NFE[[#This Row],[Valor]]-(NFE[[#This Row],[Valor]]*0.0615) -> 0 | H9: =(((NFE[[#This Row],[Valor]]-NFE[[#This Row],[Valor Real]])*0.1383)-(NFE[[#This Row],[Valor]]-NFE[[#This Row],[Valor Real]]))*-1 -> 0
D10: =NFE[[#This Row],[Valor]]*0.0615 -> 0 | E10: =NFE[[#This Row],[Valor]]*0.0768 -> 0 | F10: =NFE[[#This Row],[Valor]]-(NFE[[#This Row],[Valor]]*0.0615) -> 0 | H10: =(((NFE[[#This Row],[Valor]]-NFE[[#This Row],[Valor Real]])*0.1383)-(NFE[[#This Row],[Valor]]-NFE[[#This Row],[Valor Real]]))*-1 -> 0
D11: =NFE[[#This Row],[Valor]]*0.0615 -> 0 | E11: =NFE[[#This Row],[Valor]]*0.0768 -> 0 | F11: =NFE[[#This Row],[Valor]]-(NFE[[#This Row],[Valor]]*0.0615) -> 0 | H11: =(((NFE[[#This Row],[Valor]]-NFE[[#This Row],[Valor Real]])*0.1383)-(NFE[[#This Row],[Valor]]-NFE[[#This Row],[Valor Real]]))*-1 -> 0
D12: =NFE[[#This Row],[Valor]]*0.0615 -> 0 | E12: =NFE[[#This Row],[Valor]]*0.0768 -> 0 | F12: =NFE[[#This Row],[Valor]]-(NFE[[#This Row],[Valor]]*0.0615) -> 0 | H12: =(((NFE[[#This Row],[Valor]]-NFE[[#This Row],[Valor Real]])*0.1383)-(NFE[[#This Row],[Valor]]-NFE[[#This Row],[Valor Real]]))*-1 -> 0
D13: =NFE[[#This Row],[Valor]]*0.0615 -> 0 | E13: =NFE[[#This Row],[Valor]]*0.0768 -> 0 | F13: =NFE[[#This Row],[Valor]]-(NFE[[#This Row],[Valor]]*0.0615) -> 0 | H13: =(((NFE[[#This Row],[Valor]]-NFE[[#This Row],[Valor Real]])*0.1383)-(NFE[[#This Row],[Valor]]-NFE[[#This Row],[Valor Real]]))*-1 -> 0
D14: =NFE[[#This Row],[Valor]]*0.0615 -> 0 | E14: =NFE[[#This Row],[Valor]]*0.0768 -> 0 | F14: =NFE[[#This Row],[Valor]]-(NFE[[#This Row],[Valor]]*0.0615) -> 0 | H14: =(((NFE[[#This Row],[Valor]]-NFE[[#This Row],[Valor Real]])*0.1383)-(NFE[[#This Row],[Valor]]-NFE[[#This Row],[Valor Real]]))*-1 -> 0
... D384: =NFE[[#This Row],[Valor]]*0.0615 -> 0 | E384: =NFE[[#This Row],[Valor]]*0.0768 -> 0 | F384: =NFE[[#This Row],[Valor]]-(NFE[[#This Row],[Valor]]*0.0615) -> 0 | H384: =(((NFE[[#This Row],[Valor]]-NFE[[#This Row],[Valor Real]])*0.1383)-(NFE[[#This Row],[Valor]]-NFE[[#This Row],[Valor Real]]))*-1 -> 0

Sheet JAN
B1: 2026 | C1: 1 | D1: 2 | E1: 3 | F1: 4 | G1: 5 | H1: 6 | I1: 7 | J1: 8 | K1: 9 | L1: 10 | M1: 11 | N1: 12 | O1: 13 | P1: 14 | Q1: 15 | R1: 16 | S1: 17 | T1: 18 | U1: 19 | V1: 20 | W1: 21 | X1: 22 | Y1: 23 | Z1: 24 | AA1: 25 | AB1: 26 | AC1: 27 | AD1: 28 | AE1: 29 | AF1: 30 | AG1: 31
B2: JANEIRO | C2: =IFERROR(VALUE(C1&"/"&MONTH(1&$B$2)&"/"&$B$1),"") -> 46023 | D2: =IFERROR(VALUE(D1&"/"&MONTH(1&$B$2)&"/"&$B$1),"") -> 46024 | E2: =IFERROR(VALUE(E1&"/"&MONTH(1&$B$2)&"/"&$B$1),"") -> 46025 | F2: =IFERROR(VALUE(F1&"/"&MONTH(1&$B$2)&"/"&$B$1),"") -> 46026 | G2: =IFERROR(VALUE(G1&"/"&MONTH(1&$B$2)&"/"&$B$1),"") -> 46027 | H2: =IFERROR(VALUE(H1&"/"&MONTH(1&$B$2)&"/"&$B$1),"") -> 46028 | I2: =IFERROR(VALUE(I1&"/"&MONTH(1&$B$2)&"/"&$B$1),"") -> 46029 | J2: =IFERROR(VALUE(J1&"/"&MONTH(1&$B$2)&"/"&$B$1),"") -> 46030 | ... AG2: =IFERROR(VALUE(AG1&"/"&MONTH(1&$B$2)&"/"&$B$1),"") -> 46053
C3: =SUM(C4:C29) -> 0 | D3: =SUM(D4:D29) -> 0 | E3: =SUM(E4:E29) -> 0 | F3: =SUM(F4:F29) -> 0 | G3: =SUM(G4:G29) -> 0 | H3: =SUM(H4:H29) -> 0 | I3: =SUM(I4:I29) -> 0 | J3: =SUM(J4:J29) -> 0 | ... AG3: =SUM(AG4:AG29) -> 0
B4: {=IFERROR(_xlfn.UNIQUE(_xlfn._xlws.FILTER(DATABANK[NOME],(DATABANK[NOME]<>"")*(MONTH(DATABANK[DATA PGTO])=MONTH(1&$B$2))*(DATABANK[ENTRADA]<>""))),"")} | C4: {=IF(C$2="","",IF(IFERROR(SUM(_xlfn._xlws.FILTER(DATABANK[ENTRADA],(DATABANK[NOME]=$B4)*(DATABANK[DATA PGTO]=C$2))),"")=0,"",IFERROR(SUM(_xlfn._xlws.FILTER(DATABANK[ENTRADA],(DATABANK[NOME]=$B4)*(DATABANK[DATA PGTO]=C$2))),"")))} | D4: {=IF(D$2="","",IF(IFERROR(SUM(_xlfn._xlws.FILTER(DATABANK[ENTRADA],(DATABANK[NOME]=$B4)*(DATABANK[DATA PGTO]=D$2))),"")=0,"",IFERROR(SUM(_xlfn._xlws.FILTER(DATABANK[ENTRADA],(DATABANK[NOME]=$B4)*(DATABANK[DATA PGTO]=D$2))),"")))} | E4: {=IF(E$2="","",IF(IFERROR(SUM(_xlfn._xlws.FILTER(DATABANK[ENTRADA],(DATABANK[NOME]=$B4)*(DATABANK[DATA PGTO]=E$2))),"")=0,"",IFERROR(SUM(_xlfn._xlws.FILTER(DATABANK[ENTRADA],(DATABANK[NOME]=$B4)*(DATABANK[DATA PGTO]=E$2))),"")))} | F4: {=IF(F$2="","",IF(IFERROR(SUM(_xlfn._xlws.FILTER(DATABANK[ENTRADA],(DATABANK[NOME]=$B4)*(DATABANK[DATA PGTO]=F$2))),"")=0,"",IFERROR(SUM(_xlfn._xlws.FILTER(DATABANK[ENTRADA],(DATABANK[NOME]=$B4)*(DATABANK[DATA PGTO]=F$2))),"")))} | G4: {=IF(G$2="","",IF(IFERROR(SUM(_xlfn._xlws.FILTER(DATABANK[ENTRADA],(DATABANK[NOME]=$B4)*(DATABANK[DATA PGTO]=G$2))),"")=0,"",IFERROR(SUM(_xlfn._xlws.FILTER(DATABANK[ENTRADA],(DATABANK[NOME]=$B4)*(DATABANK[DATA PGTO]=G$2))),"")))} | H4: {=IF(H$2="","",IF(IFERROR(SUM(_xlfn._xlws.FILTER(DATABANK[ENTRADA],(DATABANK[NOME]=$B4)*(DATABANK[DATA PGTO]=H$2))),"")=0,"",IFERROR(SUM(_xlfn._xlws.FILTER(DATABANK[ENTRADA],(DATABANK[NOME]=$B4)*(DATABANK[DATA PGTO]=H$2))),"")))} | I4: {=IF(I$2="","",IF(IFERROR(SUM(_xlfn._xlws.FILTER(DATABANK[ENTRADA],(DATABANK[NOME]=$B4)*(DATABANK[DATA PGTO]=I$2))),"")=0,"",IFERROR(SUM(_xlfn._xlws.FILTER(DATABANK[ENTRADA],(DATABANK[NOME]=$B4)*(DATABANK[DATA PGTO]=I$2))),"")))} | J4: {=IF(J$2="","",IF(IFERROR(SUM(_xlfn._xlws.FILTER(DATABANK[ENTRADA],(DATABANK[NOME]=$B4)*(DATABANK[DATA PGTO]=J$2))),"")=0,"",IFERROR(SUM(_xlfn._xlws.FILTER(DATABANK[ENTRADA],(DATABANK[NOME]=$B4)*(DATABANK[DATA PGTO]=J$2))),"")))} | ... AG4: {=IF(AG$2="","",IF(IFERROR(SUM(_xlfn._xlws.FILTER(DATABANK[ENTRADA],(DATABANK[NOME]=$B4)*(DATABANK[DATA PGTO]=AG$2))),"")=0,"",IFERROR(SUM(_xlfn._xlws.FILTER(DATABANK[ENTRADA],(DATABANK[NOME]=$B4)*(DATABANK[DATA PGTO]=AG$2))),"")))}
C5: {=IF(C$2="","",IF(IFERROR(SUM(_xlfn._xlws.FILTER(DATABANK[ENTRADA],(DATABANK[NOME]=$B5)*(DATABANK[DATA PGTO]=C$2))),"")=0,"",IFERROR(SUM(_xlfn._xlws.FILTER(DATABANK[ENTRADA],(DATABANK[NOME]=$B5)*(DATABANK[DATA PGTO]=C$2))),"")))} | D5: {=IF(D$2="","",IF(IFERROR(SUM(_xlfn._xlws.FILTER(DATABANK[ENTRADA],(DATABANK[NOME]=$B5)*(DATABANK[DATA PGTO]=D$2))),"")=0,"",IFERROR(SUM(_xlfn._xlws.FILTER(DATABANK[ENTRADA],(DATABANK[NOME]=$B5)*(DATABANK[DATA PGTO]=D$2))),"")))} | E5: {=IF(E$2="","",IF(IFERROR(SUM(_xlfn._xlws.FILTER(DATABANK[ENTRADA],(DATABANK[NOME]=$B5)*(DATABANK[DATA PGTO]=E$2))),"")=0,"",IFERROR(SUM(_xlfn._xlws.FILTER(DATABANK[ENTRADA],(DATABANK[NOME]=$B5)*(DATABANK[DATA PGTO]=E$2))),"")))} | F5: {=IF(F$2="","",IF(IFERROR(SUM(_xlfn._xlws.FILTER(DATABANK[ENTRADA],(DATABANK[NOME]=$B5)*(DATABANK[DATA PGTO]=F$2))),"")=0,"",IFERROR(SUM(_xlfn._xlws.FILTER(DATABANK[ENTRADA],(DATABANK[NOME]=$B5)*(DATABANK[DATA PGTO]=F$2))),"")))} | G5: {=IF(G$2="","",IF(IFERROR(SUM(_xlfn._xlws.FILTER(DATABANK[ENTRADA],(DATABANK[NOME]=$B5)*(DATABANK[DATA PGTO]=G$2))),"")=0,"",IFERROR(SUM(_xlfn._xlws.FILTER(DATABANK[ENTRADA],(DATABANK[NOME]=$B5)*(DATABANK[DATA PGTO]=G$2))),"")))} | H5: {=IF(H$2="","",IF(IFERROR(SUM(_xlfn._xlws.FILTER(DATABANK[ENTRADA],(DATABANK[NOME]=$B5)*(DATABANK[DATA PGTO]=H$2))),"")=0,"",IFERROR(SUM(_xlfn._xlws.FILTER(DATABANK[ENTRADA],(DATABANK[NOME]=$B5)*(DATABANK[DATA PGTO]=H$2))),"")))} | I5: {=IF(I$2="","",IF(IFERROR(SUM(_xlfn._xlws.FILTER(DATABANK[ENTRADA],(DATABANK[NOME]=$B5)*(DATABANK[DATA PGTO]=I$2))),"")=0,"",IFERROR(SUM(_xlfn._xlws.FILTER(DATABANK[ENTRADA],(DATABANK[NOME]=$B5)*(DATABANK[DATA PGTO]=I$2))),"")))} | J5: {=IF(J$2="","",IF(IFERROR(SUM(_xlfn._xlws.FILTER(DATABANK[ENTRADA],(DATABANK[NOME]=$B5)*(DATABANK[DATA PGTO]=J$2))),"")=0,"",IFERROR(SUM(_xlfn._xlws.FILTER(DATABANK[ENTRADA],(DATABANK[NOME]=$B5)*(DATABANK[DATA PGTO]=J$2))),"")))} | ... AG5: {=IF(AG$2="","",IF(IFERROR(SUM(_xlfn._xlws.FILTER(DATABANK[ENTRADA],(DATABANK[NOME]=$B5)*(DATABANK[DATA PGTO]=AG$2))),"")=0,"",IFERROR(SUM(_xlfn._xlws.FILTER(DATABANK[ENTRADA],(DATABANK[NOME]=$B5)*(DATABANK[DATA PGTO]=AG$2))),"")))}
C6: {=IF(C$2="","",IF(IFERROR(SUM(_xlfn._xlws.FILTER(DATABANK[ENTRADA],(DATABANK[NOME]=$B6)*(DATABANK[DATA PGTO]=C$2))),"")=0,"",IFERROR(SUM(_xlfn._xlws.FILTER(DATABANK[ENTRADA],(DATABANK[NOME]=$B6)*(DATABANK[DATA PGTO]=C$2))),"")))} | D6: {=IF(D$2="","",IF(IFERROR(SUM(_xlfn._xlws.FILTER(DATABANK[ENTRADA],(DATABANK[NOME]=$B6)*(DATABANK[DATA PGTO]=D$2))),"")=0,"",IFERROR(SUM(_xlfn._xlws.FILTER(DATABANK[ENTRADA],(DATABANK[NOME]=$B6)*(DATABANK[DATA PGTO]=D$2))),"")))} | E6: {=IF(E$2="","",IF(IFERROR(SUM(_xlfn._xlws.FILTER(DATABANK[ENTRADA],(DATABANK[NOME]=$B6)*(DATABANK[DATA PGTO]=E$2))),"")=0,"",IFERROR(SUM(_xlfn._xlws.FILTER(DATABANK[ENTRADA],(DATABANK[NOME]=$B6)*(DATABANK[DATA PGTO]=E$2))),"")))} | F6: {=IF(F$2="","",IF(IFERROR(SUM(_xlfn._xlws.FILTER(DATABANK[ENTRADA],(DATABANK[NOME]=$B6)*(DATABANK[DATA PGTO]=F$2))),"")=0,"",IFERROR(SUM(_xlfn._xlws.FILTER(DATABANK[ENTRADA],(DATABANK[NOME]=$B6)*(DATABANK[DATA PGTO]=F$2))),"")))} | G6: {=IF(G$2="","",IF(IFERROR(SUM(_xlfn._xlws.FILTER(DATABANK[ENTRADA],(DATABANK[NOME]=$B6)*(DATABANK[DATA PGTO]=G$2))),"")=0,"",IFERROR(SUM(_xlfn._xlws.FILTER(DATABANK[ENTRADA],(DATABANK[NOME]=$B6)*(DATABANK[DATA PGTO]=G$2))),"")))} | H6: {=IF(H$2="","",IF(IFERROR(SUM(_xlfn._xlws.FILTER(DATABANK[ENTRADA],(DATABANK[NOME]=$B6)*(DATABANK[DATA PGTO]=H$2))),"")=0,"",IFERROR(SUM(_xlfn._xlws.FILTER(DATABANK[ENTRADA],(DATABANK[NOME]=$B6)*(DATABANK[DATA PGTO]=H$2))),"")))} | I6: {=IF(I$2="","",IF(IFERROR(SUM(_xlfn._xlws.FILTER(DATABANK[ENTRADA],(DATABANK[NOME]=$B6)*(DATABANK[DATA PGTO]=I$2))),"")=0,"",IFERROR(SUM(_xlfn._xlws.FILTER(DATABANK[ENTRADA],(DATABANK[NOME]=$B6)*(DATABANK[DATA PGTO]=I$2))),"")))} | J6: {=IF(J$2="","",IF(IFERROR(SUM(_xlfn._xlws.FILTER(DATABANK[ENTRADA],(DATABANK[NOME]=$B6)*(DATABANK[DATA PGTO]=J$2))),"")=0,"",IFERROR(SUM(_xlfn._xlws.FILTER(DATABANK[ENTRADA],(DATABANK[NOME]=$B6)*(DATABANK[DATA PGTO]=J$2))),"")))} | ... AG6: {=IF(AG$2="","",IF(IFERROR(SUM(_xlfn._xlws.FILTER(DATABANK[ENTRADA],(DATABANK[NOME]=$B6)*(DATABANK[DATA PGTO]=AG$2))),"")=0,"",IFERROR(SUM(_xlfn._xlws.FILTER(DATABANK[ENTRADA],(DATABANK[NOME]=$B6)*(DATABANK[DATA PGTO]=AG$2))),"")))}
C7: {=IF(C$2="","",IF(IFERROR(SUM(_xlfn._xlws.FILTER(DATABANK[ENTRADA],(DATABANK[NOME]=$B7)*(DATABANK[DATA PGTO]=C$2))),"")=0,"",IFERROR(SUM(_xlfn._xlws.FILTER(DATABANK[ENTRADA],(DATABANK[NOME]=$B7)*(DATABANK[DATA PGTO]=C$2))),"")))} | D7: {=IF(D$2="","",IF(IFERROR(SUM(_xlfn._xlws.FILTER(DATABANK[ENTRADA],(DATABANK[NOME]=$B7)*(DATABANK[DATA PGTO]=D$2))),"")=0,"",IFERROR(SUM(_xlfn._xlws.FILTER(DATABANK[ENTRADA],(DATABANK[NOME]=$B7)*(DATABANK[DATA PGTO]=D$2))),"")))} | E7: {=IF(E$2="","",IF(IFERROR(SUM(_xlfn._xlws.FILTER(DATABANK[ENTRADA],(DATABANK[NOME]=$B7)*(DATABANK[DATA PGTO]=E$2))),"")=0,"",IFERROR(SUM(_xlfn._xlws.FILTER(DATABANK[ENTRADA],(DATABANK[NOME]=$B7)*(DATABANK[DATA PGTO]=E$2))),"")))} | F7: {=IF(F$2="","",IF(IFERROR(SUM(_xlfn._xlws.FILTER(DATABANK[ENTRADA],(DATABANK[NOME]=$B7)*(DATABANK[DATA PGTO]=F$2))),"")=0,"",IFERROR(SUM(_xlfn._xlws.FILTER(DATABANK[ENTRADA],(DATABANK[NOME]=$B7)*(DATABANK[DATA PGTO]=F$2))),"")))} | G7: {=IF(G$2="","",IF(IFERROR(SUM(_xlfn._xlws.FILTER(DATABANK[ENTRADA],(DATABANK[NOME]=$B7)*(DATABANK[DATA PGTO]=G$2))),"")=0,"",IFERROR(SUM(_xlfn._xlws.FILTER(DATABANK[ENTRADA],(DATABANK[NOME]=$B7)*(DATABANK[DATA PGTO]=G$2))),"")))} | H7: {=IF(H$2="","",IF(IFERROR(SUM(_xlfn._xlws.FILTER(DATABANK[ENTRADA],(DATABANK[NOME]=$B7)*(DATABANK[DATA PGTO]=H$2))),"")=0,"",IFERROR(SUM(_xlfn._xlws.FILTER(DATABANK[ENTRADA],(DATABANK[NOME]=$B7)*(DATABANK[DATA PGTO]=H$2))),"")))} | I7: {=IF(I$2="","",IF(IFERROR(SUM(_xlfn._xlws.FILTER(DATABANK[ENTRADA],(DATABANK[NOME]=$B7)*(DATABANK[DATA PGTO]=I$2))),"")=0,"",IFERROR(SUM(_xlfn._xlws.FILTER(DATABANK[ENTRADA],(DATABANK[NOME]=$B7)*(DATABANK[DATA PGTO]=I$2))),"")))} | J7: {=IF(J$2="","",IF(IFERROR(SUM(_xlfn._xlws.FILTER(DATABANK[ENTRADA],(DATABANK[NOME]=$B7)*(DATABANK[DATA PGTO]=J$2))),"")=0,"",IFERROR(SUM(_xlfn._xlws.FILTER(DATABANK[ENTRADA],(DATABANK[NOME]=$B7)*(DATABANK[DATA PGTO]=J$2))),"")))} | ... AG7: {=IF(AG$2="","",IF(IFERROR(SUM(_xlfn._xlws.FILTER(DATABANK[ENTRADA],(DATABANK[NOME]=$B7)*(DATABANK[DATA PGTO]=AG$2))),"")=0,"",IFERROR(SUM(_xlfn._xlws.FILTER(DATABANK[ENTRADA],(DATABANK[NOME]=$B7)*(DATABANK[DATA PGTO]=AG$2))),"")))}
C8: {=IF(C$2="","",IF(IFERROR(SUM(_xlfn._xlws.FILTER(DATABANK[ENTRADA],(DATABANK[NOME]=$B8)*(DATABANK[DATA PGTO]=C$2))),"")=0,"",IFERROR(SUM(_xlfn._xlws.FILTER(DATABANK[ENTRADA],(DATABANK[NOME]=$B8)*(DATABANK[DATA PGTO]=C$2))),"")))} | D8: {=IF(D$2="","",IF(IFERROR(SUM(_xlfn._xlws.FILTER(DATABANK[ENTRADA],(DATABANK[NOME]=$B8)*(DATABANK[DATA PGTO]=D$2))),"")=0,"",IFERROR(SUM(_xlfn._xlws.FILTER(DATABANK[ENTRADA],(DATABANK[NOME]=$B8)*(DATABANK[DATA PGTO]=D$2))),"")))} | E8: {=IF(E$2="","",IF(IFERROR(SUM(_xlfn._xlws.FILTER(DATABANK[ENTRADA],(DATABANK[NOME]=$B8)*(DATABANK[DATA PGTO]=E$2))),"")=0,"",IFERROR(SUM(_xlfn._xlws.FILTER(DATABANK[ENTRADA],(DATABANK[NOME]=$B8)*(DATABANK[DATA PGTO]=E$2))),"")))} | F8: {=IF(F$2="","",IF(IFERROR(SUM(_xlfn._xlws.FILTER(DATABANK[ENTRADA],(DATABANK[NOME]=$B8)*(DATABANK[DATA PGTO]=F$2))),"")=0,"",IFERROR(SUM(_xlfn._xlws.FILTER(DATABANK[ENTRADA],(DATABANK[NOME]=$B8)*(DATABANK[DATA PGTO]=F$2))),"")))} | G8: {=IF(G$2="","",IF(IFERROR(SUM(_xlfn._xlws.FILTER(DATABANK[ENTRADA],(DATABANK[NOME]=$B8)*(DATABANK[DATA PGTO]=G$2))),"")=0,"",IFERROR(SUM(_xlfn._xlws.FILTER(DATABANK[ENTRADA],(DATABANK[NOME]=$B8)*(DATABANK[DATA PGTO]=G$2))),"")))} | H8: {=IF(H$2="","",IF(IFERROR(SUM(_xlfn._xlws.FILTER(DATABANK[ENTRADA],(DATABANK[NOME]=$B8)*(DATABANK[DATA PGTO]=H$2))),"")=0,"",IFERROR(SUM(_xlfn._xlws.FILTER(DATABANK[ENTRADA],(DATABANK[NOME]=$B8)*(DATABANK[DATA PGTO]=H$2))),"")))} | I8: {=IF(I$2="","",IF(IFERROR(SUM(_xlfn._xlws.FILTER(DATABANK[ENTRADA],(DATABANK[NOME]=$B8)*(DATABANK[DATA PGTO]=I$2))),"")=0,"",IFERROR(SUM(_xlfn._xlws.FILTER(DATABANK[ENTRADA],(DATABANK[NOME]=$B8)*(DATABANK[DATA PGTO]=I$2))),"")))} | J8: {=IF(J$2="","",IF(IFERROR(SUM(_xlfn._xlws.FILTER(DATABANK[ENTRADA],(DATABANK[NOME]=$B8)*(DATABANK[DATA PGTO]=J$2))),"")=0,"",IFERROR(SUM(_xlfn._xlws.FILTER(DATABANK[ENTRADA],(DATABANK[NOME]=$B8)*(DATABANK[DATA PGTO]=J$2))),"")))} | ... AG8: {=IF(AG$2="","",IF(IFERROR(SUM(_xlfn._xlws.FILTER(DATABANK[ENTRADA],(DATABANK[NOME]=$B8)*(DATABANK[DATA PGTO]=AG$2))),"")=0,"",IFERROR(SUM(_xlfn._xlws.FILTER(DATABANK[ENTRADA],(DATABANK[NOME]=$B8)*(DATABANK[DATA PGTO]=AG$2))),"")))}
C9: {=IF(C$2="","",IF(IFERROR(SUM(_xlfn._xlws.FILTER(DATABANK[ENTRADA],(DATABANK[NOME]=$B9)*(DATABANK[DATA PGTO]=C$2))),"")=0,"",IFERROR(SUM(_xlfn._xlws.FILTER(DATABANK[ENTRADA],(DATABANK[NOME]=$B9)*(DATABANK[DATA PGTO]=C$2))),"")))} | D9: {=IF(D$2="","",IF(IFERROR(SUM(_xlfn._xlws.FILTER(DATABANK[ENTRADA],(DATABANK[NOME]=$B9)*(DATABANK[DATA PGTO]=D$2))),"")=0,"",IFERROR(SUM(_xlfn._xlws.FILTER(DATABANK[ENTRADA],(DATABANK[NOME]=$B9)*(DATABANK[DATA PGTO]=D$2))),"")))} | E9: {=IF(E$2="","",IF(IFERROR(SUM(_xlfn._xlws.FILTER(DATABANK[ENTRADA],(DATABANK[NOME]=$B9)*(DATABANK[DATA PGTO]=E$2))),"")=0,"",IFERROR(SUM(_xlfn._xlws.FILTER(DATABANK[ENTRADA],(DATABANK[NOME]=$B9)*(DATABANK[DATA PGTO]=E$2))),"")))} | F9: {=IF(F$2="","",IF(IFERROR(SUM(_xlfn._xlws.FILTER(DATABANK[ENTRADA],(DATABANK[NOME]=$B9)*(DATABANK[DATA PGTO]=F$2))),"")=0,"",IFERROR(SUM(_xlfn._xlws.FILTER(DATABANK[ENTRADA],(DATABANK[NOME]=$B9)*(DATABANK[DATA PGTO]=F$2))),"")))} | G9: {=IF(G$2="","",IF(IFERROR(SUM(_xlfn._xlws.FILTER(DATABANK[ENTRADA],(DATABANK[NOME]=$B9)*(DATABANK[DATA PGTO]=G$2))),"")=0,"",IFERROR(SUM(_xlfn._xlws.FILTER(DATABANK[ENTRADA],(DATABANK[NOME]=$B9)*(DATABANK[DATA PGTO]=G$2))),"")))} | H9: {=IF(H$2="","",IF(IFERROR(SUM(_xlfn._xlws.FILTER(DATABANK[ENTRADA],(DATABANK[NOME]=$B9)*(DATABANK[DATA PGTO]=H$2))),"")=0,"",IFERROR(SUM(_xlfn._xlws.FILTER(DATABANK[ENTRADA],(DATABANK[NOME]=$B9)*(DATABANK[DATA PGTO]=H$2))),"")))} | I9: {=IF(I$2="","",IF(IFERROR(SUM(_xlfn._xlws.FILTER(DATABANK[ENTRADA],(DATABANK[NOME]=$B9)*(DATABANK[DATA PGTO]=I$2))),"")=0,"",IFERROR(SUM(_xlfn._xlws.FILTER(DATABANK[ENTRADA],(DATABANK[NOME]=$B9)*(DATABANK[DATA PGTO]=I$2))),"")))} | J9: {=IF(J$2="","",IF(IFERROR(SUM(_xlfn._xlws.FILTER(DATABANK[ENTRADA],(DATABANK[NOME]=$B9)*(DATABANK[DATA PGTO]=J$2))),"")=0,"",IFERROR(SUM(_xlfn._xlws.FILTER(DATABANK[ENTRADA],(DATABANK[NOME]=$B9)*(DATABANK[DATA PGTO]=J$2))),"")))} | ... AG9: {=IF(AG$2="","",IF(IFERROR(SUM(_xlfn._xlws.FILTER(DATABANK[ENTRADA],(DATABANK[NOME]=$B9)*(DATABANK[DATA PGTO]=AG$2))),"")=0,"",IFERROR(SUM(_xlfn._xlws.FILTER(DATABANK[ENTRADA],(DATABANK[NOME]=$B9)*(DATABANK[DATA PGTO]=AG$2))),"")))}
C10: {=IF(C$2="","",IF(IFERROR(SUM(_xlfn._xlws.FILTER(DATABANK[ENTRADA],(DATABANK[NOME]=$B10)*(DATABANK[DATA PGTO]=C$2))),"")=0,"",IFERROR(SUM(_xlfn._xlws.FILTER(DATABANK[ENTRADA],(DATABANK[NOME]=$B10)*(DATABANK[DATA PGTO]=C$2))),"")))} | D10: {=IF(D$2="","",IF(IFERROR(SUM(_xlfn._xlws.FILTER(DATABANK[ENTRADA],(DATABANK[NOME]=$B10)*(DATABANK[DATA PGTO]=D$2))),"")=0,"",IFERROR(SUM(_xlfn._xlws.FILTER(DATABANK[ENTRADA],(DATABANK[NOME]=$B10)*(DATABANK[DATA PGTO]=D$2))),"")))} | E10: {=IF(E$2="","",IF(IFERROR(SUM(_xlfn._xlws.FILTER(DATABANK[ENTRADA],(DATABANK[NOME]=$B10)*(DATABANK[DATA PGTO]=E$2))),"")=0,"",IFERROR(SUM(_xlfn._xlws.FILTER(DATABANK[ENTRADA],(DATABANK[NOME]=$B10)*(DATABANK[DATA PGTO]=E$2))),"")))} | F10: {=IF(F$2="","",IF(IFERROR(SUM(_xlfn._xlws.FILTER(DATABANK[ENTRADA],(DATABANK[NOME]=$B10)*(DATABANK[DATA PGTO]=F$2))),"")=0,"",IFERROR(SUM(_xlfn._xlws.FILTER(DATABANK[ENTRADA],(DATABANK[NOME]=$B10)*(DATABANK[DATA PGTO]=F$2))),"")))} | G10: {=IF(G$2="","",IF(IFERROR(SUM(_xlfn._xlws.FILTER(DATABANK[ENTRADA],(DATABANK[NOME]=$B10)*(DATABANK[DATA PGTO]=G$2))),"")=0,"",IFERROR(SUM(_xlfn._xlws.FILTER(DATABANK[ENTRADA],(DATABANK[NOME]=$B10)*(DATABANK[DATA PGTO]=G$2))),"")))} | H10: {=IF(H$2="","",IF(IFERROR(SUM(_xlfn._xlws.FILTER(DATABANK[ENTRADA],(DATABANK[NOME]=$B10)*(DATABANK[DATA PGTO]=H$2))),"")=0,"",IFERROR(SUM(_xlfn._xlws.FILTER(DATABANK[ENTRADA],(DATABANK[NOME]=$B10)*(DATABANK[DATA PGTO]=H$2))),"")))} | I10: {=IF(I$2="","",IF(IFERROR(SUM(_xlfn._xlws.FILTER(DATABANK[ENTRADA],(DATABANK[NOME]=$B10)*(DATABANK[DATA PGTO]=I$2))),"")=0,"",IFERROR(SUM(_xlfn._xlws.FILTER(DATABANK[ENTRADA],(DATABANK[NOME]=$B10)*(DATABANK[DATA PGTO]=I$2))),"")))} | J10: {=IF(J$2="","",IF(IFERROR(SUM(_xlfn._xlws.FILTER(DATABANK[ENTRADA],(DATABANK[NOME]=$B10)*(DATABANK[DATA PGTO]=J$2))),"")=0,"",IFERROR(SUM(_xlfn._xlws.FILTER(DATABANK[ENTRADA],(DATABANK[NOME]=$B10)*(DATABANK[DATA PGTO]=J$2))),"")))} | ... AG10: {=IF(AG$2="","",IF(IFERROR(SUM(_xlfn._xlws.FILTER(DATABANK[ENTRADA],(DATABANK[NOME]=$B10)*(DATABANK[DATA PGTO]=AG$2))),"")=0,"",IFERROR(SUM(_xlfn._xlws.FILTER(DATABANK[ENTRADA],(DATABANK[NOME]=$B10)*(DATABANK[DATA PGTO]=AG$2))),"")))}
C11: {=IF(C$2="","",IF(IFERROR(SUM(_xlfn._xlws.FILTER(DATABANK[ENTRADA],(DATABANK[NOME]=$B11)*(DATABANK[DATA PGTO]=C$2))),"")=0,"",IFERROR(SUM(_xlfn._xlws.FILTER(DATABANK[ENTRADA],(DATABANK[NOME]=$B11)*(DATABANK[DATA PGTO]=C$2))),"")))} | D11: {=IF(D$2="","",IF(IFERROR(SUM(_xlfn._xlws.FILTER(DATABANK[ENTRADA],(DATABANK[NOME]=$B11)*(DATABANK[DATA PGTO]=D$2))),"")=0,"",IFERROR(SUM(_xlfn._xlws.FILTER(DATABANK[ENTRADA],(DATABANK[NOME]=$B11)*(DATABANK[DATA PGTO]=D$2))),"")))} | E11: {=IF(E$2="","",IF(IFERROR(SUM(_xlfn._xlws.FILTER(DATABANK[ENTRADA],(DATABANK[NOME]=$B11)*(DATABANK[DATA PGTO]=E$2))),"")=0,"",IFERROR(SUM(_xlfn._xlws.FILTER(DATABANK[ENTRADA],(DATABANK[NOME]=$B11)*(DATABANK[DATA PGTO]=E$2))),"")))} | F11: {=IF(F$2="","",IF(IFERROR(SUM(_xlfn._xlws.FILTER(DATABANK[ENTRADA],(DATABANK[NOME]=$B11)*(DATABANK[DATA PGTO]=F$2))),"")=0,"",IFERROR(SUM(_xlfn._xlws.FILTER(DATABANK[ENTRADA],(DATABANK[NOME]=$B11)*(DATABANK[DATA PGTO]=F$2))),"")))} | G11: {=IF(G$2="","",IF(IFERROR(SUM(_xlfn._xlws.FILTER(DATABANK[ENTRADA],(DATABANK[NOME]=$B11)*(DATABANK[DATA PGTO]=G$2))),"")=0,"",IFERROR(SUM(_xlfn._xlws.FILTER(DATABANK[ENTRADA],(DATABANK[NOME]=$B11)*(DATABANK[DATA PGTO]=G$2))),"")))} | H11: {=IF(H$2="","",IF(IFERROR(SUM(_xlfn._xlws.FILTER(DATABANK[ENTRADA],(DATABANK[NOME]=$B11)*(DATABANK[DATA PGTO]=H$2))),"")=0,"",IFERROR(SUM(_xlfn._xlws.FILTER(DATABANK[ENTRADA],(DATABANK[NOME]=$B11)*(DATABANK[DATA PGTO]=H$2))),"")))} | I11: {=IF(I$2="","",IF(IFERROR(SUM(_xlfn._xlws.FILTER(DATABANK[ENTRADA],(DATABANK[NOME]=$B11)*(DATABANK[DATA PGTO]=I$2))),"")=0,"",IFERROR(SUM(_xlfn._xlws.FILTER(DATABANK[ENTRADA],(DATABANK[NOME]=$B11)*(DATABANK[DATA PGTO]=I$2))),"")))} | J11: {=IF(J$2="","",IF(IFERROR(SUM(_xlfn._xlws.FILTER(DATABANK[ENTRADA],(DATABANK[NOME]=$B11)*(DATABANK[DATA PGTO]=J$2))),"")=0,"",IFERROR(SUM(_xlfn._xlws.FILTER(DATABANK[ENTRADA],(DATABANK[NOME]=$B11)*(DATABANK[DATA PGTO]=J$2))),"")))} | ... AG11: {=IF(AG$2="","",IF(IFERROR(SUM(_xlfn._xlws.FILTER(DATABANK[ENTRADA],(DATABANK[NOME]=$B11)*(DATABANK[DATA PGTO]=AG$2))),"")=0,"",IFERROR(SUM(_xlfn._xlws.FILTER(DATABANK[ENTRADA],(DATABANK[NOME]=$B11)*(DATABANK[DATA PGTO]=AG$2))),"")))}
C12: {=IF(C$2="","",IF(IFERROR(SUM(_xlfn._xlws.FILTER(DATABANK[ENTRADA],(DATABANK[NOME]=$B12)*(DATABANK[DATA PGTO]=C$2))),"")=0,"",IFERROR(SUM(_xlfn._xlws.FILTER(DATABANK[ENTRADA],(DATABANK[NOME]=$B12)*(DATABANK[DATA PGTO]=C$2))),"")))} | D12: {=IF(D$2="","",IF(IFERROR(SUM(_xlfn._xlws.FILTER(DATABANK[ENTRADA],(DATABANK[NOME]=$B12)*(DATABANK[DATA PGTO]=D$2))),"")=0,"",IFERROR(SUM(_xlfn._xlws.FILTER(DATABANK[ENTRADA],(DATABANK[NOME]=$B12)*(DATABANK[DATA PGTO]=D$2))),"")))} | E12: {=IF(E$2="","",IF(IFERROR(SUM(_xlfn._xlws.FILTER(DATABANK[ENTRADA],(DATABANK[NOME]=$B12)*(DATABANK[DATA PGTO]=E$2))),"")=0,"",IFERROR(SUM(_xlfn._xlws.FILTER(DATABANK[ENTRADA],(DATABANK[NOME]=$B12)*(DATABANK[DATA PGTO]=E$2))),"")))} | F12: {=IF(F$2="","",IF(IFERROR(SUM(_xlfn._xlws.FILTER(DATABANK[ENTRADA],(DATABANK[NOME]=$B12)*(DATABANK[DATA PGTO]=F$2))),"")=0,"",IFERROR(SUM(_xlfn._xlws.FILTER(DATABANK[ENTRADA],(DATABANK[NOME]=$B12)*(DATABANK[DATA PGTO]=F$2))),"")))} | G12: {=IF(G$2="","",IF(IFERROR(SUM(_xlfn._xlws.FILTER(DATABANK[ENTRADA],(DATABANK[NOME]=$B12)*(DATABANK[DATA PGTO]=G$2))),"")=0,"",IFERROR(SUM(_xlfn._xlws.FILTER(DATABANK[ENTRADA],(DATABANK[NOME]=$B12)*(DATABANK[DATA PGTO]=G$2))),"")))} | H12: {=IF(H$2="","",IF(IFERROR(SUM(_xlfn._xlws.FILTER(DATABANK[ENTRADA],(DATABANK[NOME]=$B12)*(DATABANK[DATA PGTO]=H$2))),"")=0,"",IFERROR(SUM(_xlfn._xlws.FILTER(DATABANK[ENTRADA],(DATABANK[NOME]=$B12)*(DATABANK[DATA PGTO]=H$2))),"")))} | I12: {=IF(I$2="","",IF(IFERROR(SUM(_xlfn._xlws.FILTER(DATABANK[ENTRADA],(DATABANK[NOME]=$B12)*(DATABANK[DATA PGTO]=I$2))),"")=0,"",IFERROR(SUM(_xlfn._xlws.FILTER(DATABANK[ENTRADA],(DATABANK[NOME]=$B12)*(DATABANK[DATA PGTO]=I$2))),"")))} | J12: {=IF(J$2="","",IF(IFERROR(SUM(_xlfn._xlws.FILTER(DATABANK[ENTRADA],(DATABANK[NOME]=$B12)*(DATABANK[DATA PGTO]=J$2))),"")=0,"",IFERROR(SUM(_xlfn._xlws.FILTER(DATABANK[ENTRADA],(DATABANK[NOME]=$B12)*(DATABANK[DATA PGTO]=J$2))),"")))} | ... AG12: {=IF(AG$2="","",IF(IFERROR(SUM(_xlfn._xlws.FILTER(DATABANK[ENTRADA],(DATABANK[NOME]=$B12)*(DATABANK[DATA PGTO]=AG$2))),"")=0,"",IFERROR(SUM(_xlfn._xlws.FILTER(DATABANK[ENTRADA],(DATABANK[NOME]=$B12)*(DATABANK[DATA PGTO]=AG$2))),"")))}
C13: {=IF(C$2="","",IF(IFERROR(SUM(_xlfn._xlws.FILTER(DATABANK[ENTRADA],(DATABANK[NOME]=$B13)*(DATABANK[DATA PGTO]=C$2))),"")=0,"",IFERROR(SUM(_xlfn._xlws.FILTER(DATABANK[ENTRADA],(DATABANK[NOME]=$B13)*(DATABANK[DATA PGTO]=C$2))),"")))} | D13: {=IF(D$2="","",IF(IFERROR(SUM(_xlfn._xlws.FILTER(DATABANK[ENTRADA],(DATABANK[NOME]=$B13)*(DATABANK[DATA PGTO]=D$2))),"")=0,"",IFERROR(SUM(_xlfn._xlws.FILTER(DATABANK[ENTRADA],(DATABANK[NOME]=$B13)*(DATABANK[DATA PGTO]=D$2))),"")))} | E13: {=IF(E$2="","",IF(IFERROR(SUM(_xlfn._xlws.FILTER(DATABANK[ENTRADA],(DATABANK[NOME]=$B13)*(DATABANK[DATA PGTO]=E$2))),"")=0,"",IFERROR(SUM(_xlfn._xlws.FILTER(DATABANK[ENTRADA],(DATABANK[NOME]=$B13)*(DATABANK[DATA PGTO]=E$2))),"")))} | F13: {=IF(F$2="","",IF(IFERROR(SUM(_xlfn._xlws.FILTER(DATABANK[ENTRADA],(DATABANK[NOME]=$B13)*(DATABANK[DATA PGTO]=F$2))),"")=0,"",IFERROR(SUM(_xlfn._xlws.FILTER(DATABANK[ENTRADA],(DATABANK[NOME]=$B13)*(DATABANK[DATA PGTO]=F$2))),"")))} | G13: {=IF(G$2="","",IF(IFERROR(SUM(_xlfn._xlws.FILTER(DATABANK[ENTRADA],(DATABANK[NOME]=$B13)*(DATABANK[DATA PGTO]=G$2))),"")=0,"",IFERROR(SUM(_xlfn._xlws.FILTER(DATABANK[ENTRADA],(DATABANK[NOME]=$B13)*(DATABANK[DATA PGTO]=G$2))),"")))} | H13: {=IF(H$2="","",IF(IFERROR(SUM(_xlfn._xlws.FILTER(DATABANK[ENTRADA],(DATABANK[NOME]=$B13)*(DATABANK[DATA PGTO]=H$2))),"")=0,"",IFERROR(SUM(_xlfn._xlws.FILTER(DATABANK[ENTRADA],(DATABANK[NOME]=$B13)*(DATABANK[DATA PGTO]=H$2))),"")))} | I13: {=IF(I$2="","",IF(IFERROR(SUM(_xlfn._xlws.FILTER(DATABANK[ENTRADA],(DATABANK[NOME]=$B13)*(DATABANK[DATA PGTO]=I$2))),"")=0,"",IFERROR(SUM(_xlfn._xlws.FILTER(DATABANK[ENTRADA],(DATABANK[NOME]=$B13)*(DATABANK[DATA PGTO]=I$2))),"")))} | J13: {=IF(J$2="","",IF(IFERROR(SUM(_xlfn._xlws.FILTER(DATABANK[ENTRADA],(DATABANK[NOME]=$B13)*(DATABANK[DATA PGTO]=J$2))),"")=0,"",IFERROR(SUM(_xlfn._xlws.FILTER(DATABANK[ENTRADA],(DATABANK[NOME]=$B13)*(DATABANK[DATA PGTO]=J$2))),"")))} | ... AG13: {=IF(AG$2="","",IF(IFERROR(SUM(_xlfn._xlws.FILTER(DATABANK[ENTRADA],(DATABANK[NOME]=$B13)*(DATABANK[DATA PGTO]=AG$2))),"")=0,"",IFERROR(SUM(_xlfn._xlws.FILTER(DATABANK[ENTRADA],(DATABANK[NOME]=$B13)*(DATABANK[DATA PGTO]=AG$2))),"")))}
C14: {=IF(C$2="","",IF(IFERROR(SUM(_xlfn._xlws.FILTER(DATABANK[ENTRADA],(DATABANK[NOME]=$B14)*(DATABANK[DATA PGTO]=C$2))),"")=0,"",IFERROR(SUM(_xlfn._xlws.FILTER(DATABANK[ENTRADA],(DATABANK[NOME]=$B14)*(DATABANK[DATA PGTO]=C$2))),"")))} | D14: {=IF(D$2="","",IF(IFERROR(SUM(_xlfn._xlws.FILTER(DATABANK[ENTRADA],(DATABANK[NOME]=$B14)*(DATABANK[DATA PGTO]=D$2))),"")=0,"",IFERROR(SUM(_xlfn._xlws.FILTER(DATABANK[ENTRADA],(DATABANK[NOME]=$B14)*(DATABANK[DATA PGTO]=D$2))),"")))} | E14: {=IF(E$2="","",IF(IFERROR(SUM(_xlfn._xlws.FILTER(DATABANK[ENTRADA],(DATABANK[NOME]=$B14)*(DATABANK[DATA PGTO]=E$2))),"")=0,"",IFERROR(SUM(_xlfn._xlws.FILTER(DATABANK[ENTRADA],(DATABANK[NOME]=$B14)*(DATABANK[DATA PGTO]=E$2))),"")))} | F14: {=IF(F$2="","",IF(IFERROR(SUM(_xlfn._xlws.FILTER(DATABANK[ENTRADA],(DATABANK[NOME]=$B14)*(DATABANK[DATA PGTO]=F$2))),"")=0,"",IFERROR(SUM(_xlfn._xlws.FILTER(DATABANK[ENTRADA],(DATABANK[NOME]=$B14)*(DATABANK[DATA PGTO]=F$2))),"")))} | G14: {=IF(G$2="","",IF(IFERROR(SUM(_xlfn._xlws.FILTER(DATABANK[ENTRADA],(DATABANK[NOME]=$B14)*(DATABANK[DATA PGTO]=G$2))),"")=0,"",IFERROR(SUM(_xlfn._xlws.FILTER(DATABANK[ENTRADA],(DATABANK[NOME]=$B14)*(DATABANK[DATA PGTO]=G$2))),"")))} | H14: {=IF(H$2="","",IF(IFERROR(SUM(_xlfn._xlws.FILTER(DATABANK[ENTRADA],(DATABANK[NOME]=$B14)*(DATABANK[DATA PGTO]=H$2))),"")=0,"",IFERROR(SUM(_xlfn._xlws.FILTER(DATABANK[ENTRADA],(DATABANK[NOME]=$B14)*(DATABANK[DATA PGTO]=H$2))),"")))} | I14: {=IF(I$2="","",IF(IFERROR(SUM(_xlfn._xlws.FILTER(DATABANK[ENTRADA],(DATABANK[NOME]=$B14)*(DATABANK[DATA PGTO]=I$2))),"")=0,"",IFERROR(SUM(_xlfn._xlws.FILTER(DATABANK[ENTRADA],(DATABANK[NOME]=$B14)*(DATABANK[DATA PGTO]=I$2))),"")))} | J14: {=IF(J$2="","",IF(IFERROR(SUM(_xlfn._xlws.FILTER(DATABANK[ENTRADA],(DATABANK[NOME]=$B14)*(DATABANK[DATA PGTO]=J$2))),"")=0,"",IFERROR(SUM(_xlfn._xlws.FILTER(DATABANK[ENTRADA],(DATABANK[NOME]=$B14)*(DATABANK[DATA PGTO]=J$2))),"")))} | ... AG14: {=IF(AG$2="","",IF(IFERROR(SUM(_xlfn._xlws.FILTER(DATABANK[ENTRADA],(DATABANK[NOME]=$B14)*(DATABANK[DATA PGTO]=AG$2))),"")=0,"",IFERROR(SUM(_xlfn._xlws.FILTER(DATABANK[ENTRADA],(DATABANK[NOME]=$B14)*(DATABANK[DATA PGTO]=AG$2))),"")))}
C15: {=IF(C$2="","",IF(IFERROR(SUM(_xlfn._xlws.FILTER(DATABANK[ENTRADA],(DATABANK[NOME]=$B15)*(DATABANK[DATA PGTO]=C$2))),"")=0,"",IFERROR(SUM(_xlfn._xlws.FILTER(DATABANK[ENTRADA],(DATABANK[NOME]=$B15)*(DATABANK[DATA PGTO]=C$2))),"")))} | D15: {=IF(D$2="","",IF(IFERROR(SUM(_xlfn._xlws.FILTER(DATABANK[ENTRADA],(DATABANK[NOME]=$B15)*(DATABANK[DATA PGTO]=D$2))),"")=0,"",IFERROR(SUM(_xlfn._xlws.FILTER(DATABANK[ENTRADA],(DATABANK[NOME]=$B15)*(DATABANK[DATA PGTO]=D$2))),"")))} | E15: {=IF(E$2="","",IF(IFERROR(SUM(_xlfn._xlws.FILTER(DATABANK[ENTRADA],(DATABANK[NOME]=$B15)*(DATABANK[DATA PGTO]=E$2))),"")=0,"",IFERROR(SUM(_xlfn._xlws.FILTER(DATABANK[ENTRADA],(DATABANK[NOME]=$B15)*(DATABANK[DATA PGTO]=E$2))),"")))} | F15: {=IF(F$2="","",IF(IFERROR(SUM(_xlfn._xlws.FILTER(DATABANK[ENTRADA],(DATABANK[NOME]=$B15)*(DATABANK[DATA PGTO]=F$2))),"")=0,"",IFERROR(SUM(_xlfn._xlws.FILTER(DATABANK[ENTRADA],(DATABANK[NOME]=$B15)*(DATABANK[DATA PGTO]=F$2))),"")))} | G15: {=IF(G$2="","",IF(IFERROR(SUM(_xlfn._xlws.FILTER(DATABANK[ENTRADA],(DATABANK[NOME]=$B15)*(DATABANK[DATA PGTO]=G$2))),"")=0,"",IFERROR(SUM(_xlfn._xlws.FILTER(DATABANK[ENTRADA],(DATABANK[NOME]=$B15)*(DATABANK[DATA PGTO]=G$2))),"")))} | H15: {=IF(H$2="","",IF(IFERROR(SUM(_xlfn._xlws.FILTER(DATABANK[ENTRADA],(DATABANK[NOME]=$B15)*(DATABANK[DATA PGTO]=H$2))),"")=0,"",IFERROR(SUM(_xlfn._xlws.FILTER(DATABANK[ENTRADA],(DATABANK[NOME]=$B15)*(DATABANK[DATA PGTO]=H$2))),"")))} | I15: {=IF(I$2="","",IF(IFERROR(SUM(_xlfn._xlws.FILTER(DATABANK[ENTRADA],(DATABANK[NOME]=$B15)*(DATABANK[DATA PGTO]=I$2))),"")=0,"",IFERROR(SUM(_xlfn._xlws.FILTER(DATABANK[ENTRADA],(DATABANK[NOME]=$B15)*(DATABANK[DATA PGTO]=I$2))),"")))} | J15: {=IF(J$2="","",IF(IFERROR(SUM(_xlfn._xlws.FILTER(DATABANK[ENTRADA],(DATABANK[NOME]=$B15)*(DATABANK[DATA PGTO]=J$2))),"")=0,"",IFERROR(SUM(_xlfn._xlws.FILTER(DATABANK[ENTRADA],(DATABANK[NOME]=$B15)*(DATABANK[DATA PGTO]=J$2))),"")))} | ... AG15: {=IF(AG$2="","",IF(IFERROR(SUM(_xlfn._xlws.FILTER(DATABANK[ENTRADA],(DATABANK[NOME]=$B15)*(DATABANK[DATA PGTO]=AG$2))),"")=0,"",IFERROR(SUM(_xlfn._xlws.FILTER(DATABANK[ENTRADA],(DATABANK[NOME]=$B15)*(DATABANK[DATA PGTO]=AG$2))),"")))}
C16: {=IF(C$2="","",IF(IFERROR(SUM(_xlfn._xlws.FILTER(DATABANK[ENTRADA],(DATABANK[NOME]=$B16)*(DATABANK[DATA PGTO]=C$2))),"")=0,"",IFERROR(SUM(_xlfn._xlws.FILTER(DATABANK[ENTRADA],(DATABANK[NOME]=$B16)*(DATABANK[DATA PGTO]=C$2))),"")))} | D16: {=IF(D$2="","",IF(IFERROR(SUM(_xlfn._xlws.FILTER(DATABANK[ENTRADA],(DATABANK[NOME]=$B16)*(DATABANK[DATA PGTO]=D$2))),"")=0,"",IFERROR(SUM(_xlfn._xlws.FILTER(DATABANK[ENTRADA],(DATABANK[NOME]=$B16)*(DATABANK[DATA PGTO]=D$2))),"")))} | E16: {=IF(E$2="","",IF(IFERROR(SUM(_xlfn._xlws.FILTER(DATABANK[ENTRADA],(DATABANK[NOME]=$B16)*(DATABANK[DATA PGTO]=E$2))),"")=0,"",IFERROR(SUM(_xlfn._xlws.FILTER(DATABANK[ENTRADA],(DATABANK[NOME]=$B16)*(DATABANK[DATA PGTO]=E$2))),"")))} | F16: {=IF(F$2="","",IF(IFERROR(SUM(_xlfn._xlws.FILTER(DATABANK[ENTRADA],(DATABANK[NOME]=$B16)*(DATABANK[DATA PGTO]=F$2))),"")=0,"",IFERROR(SUM(_xlfn._xlws.FILTER(DATABANK[ENTRADA],(DATABANK[NOME]=$B16)*(DATABANK[DATA PGTO]=F$2))),"")))} | G16: {=IF(G$2="","",IF(IFERROR(SUM(_xlfn._xlws.FILTER(DATABANK[ENTRADA],(DATABANK[NOME]=$B16)*(DATABANK[DATA PGTO]=G$2))),"")=0,"",IFERROR(SUM(_xlfn._xlws.FILTER(DATABANK[ENTRADA],(DATABANK[NOME]=$B16)*(DATABANK[DATA PGTO]=G$2))),"")))} | H16: {=IF(H$2="","",IF(IFERROR(SUM(_xlfn._xlws.FILTER(DATABANK[ENTRADA],(DATABANK[NOME]=$B16)*(DATABANK[DATA PGTO]=H$2))),"")=0,"",IFERROR(SUM(_xlfn._xlws.FILTER(DATABANK[ENTRADA],(DATABANK[NOME]=$B16)*(DATABANK[DATA PGTO]=H$2))),"")))} | I16: {=IF(I$2="","",IF(IFERROR(SUM(_xlfn._xlws.FILTER(DATABANK[ENTRADA],(DATABANK[NOME]=$B16)*(DATABANK[DATA PGTO]=I$2))),"")=0,"",IFERROR(SUM(_xlfn._xlws.FILTER(DATABANK[ENTRADA],(DATABANK[NOME]=$B16)*(DATABANK[DATA PGTO]=I$2))),"")))} | J16: {=IF(J$2="","",IF(IFERROR(SUM(_xlfn._xlws.FILTER(DATABANK[ENTRADA],(DATABANK[NOME]=$B16)*(DATABANK[DATA PGTO]=J$2))),"")=0,"",IFERROR(SUM(_xlfn._xlws.FILTER(DATABANK[ENTRADA],(DATABANK[NOME]=$B16)*(DATABANK[DATA PGTO]=J$2))),"")))} | ... AG16: {=IF(AG$2="","",IF(IFERROR(SUM(_xlfn._xlws.FILTER(DATABANK[ENTRADA],(DATABANK[NOME]=$B16)*(DATABANK[DATA PGTO]=AG$2))),"")=0,"",IFERROR(SUM(_xlfn._xlws.FILTER(DATABANK[ENTRADA],(DATABANK[NOME]=$B16)*(DATABANK[DATA PGTO]=AG$2))),"")))}
